Workbook

Sheet README
B1: J-REITオフィス系16法人 保有物件・収支比較データベース
A3: 【完成】全16法人・1,273行(物件1,203+期中譲渡等+法人一括16行)の投入・5段階検証を完了(2026/8/8) | B3: 1. 基本情報
A4: 16法人取得価格合計: 8,485,612百万円(約8.49兆円)。各法人とも最新決算期短信と照合済(鑑定評価額・NLA・テナント数は原則完全一致、取得・帳簿の物件別合算と合計欄の差は百万円未満切捨て/四捨五入(HLCのみ)の累積として全件注記済) | B4: 作成日 | C4: 2026年8月7日
A5: 開示水準の類型: ①費用内訳フル開示=MHR・NUD・HLC(46/67)・JRE(76/79)・MTR(18/20) ②収益のみ開示=NBF・GOR・DOI・ICG・JEI・JPR・SHR・HFR・KDX ③法人一括のみ=TRE・SKR。E列(開示区分)で判別可能 | B5: 築年数計算の基準日 | C5: 46241
A6: 原資料内の系統的丸め: 科目別切捨てによる内訳チェック(U列)1〜5千円・掲載損益との1千円差(多数法人)、KDXの3層切捨て構造(物件<用途小計<総合計)等はすべて備考に注記。数値は開示掲載値のまま転記(改変ゼロ) | B6: 目的 | C6: オフィス系J-REIT16法人の保有物件の基本情報と物件別収支（収入・費用・利益）を、法人をまたいで同一基準で比較できる形で管理する。
A7: 次回更新の目安: NBF第50期(2026/8中旬)→JEI 2026年6月期(8月下旬)→TRE第46期(9/14)→HLC第25期(10月中旬)→MTR第49期(10月下旬)→JRE第50期・SKR(11月・SKRは上場廃止の可能性)→KDX第43期・SHR第24期(12月中旬)→HFR第50期(2027/1)。SKRはTOB成立時に更新対象から除外検討 | B7: 対象決算期 | C7: 各法人の最新決算期（法人マスタ「最新決算期」列参照）。決算期は法人ごとに異なるため、比較の際は期間月数と年換算値を用いること。
B9: 2. シート構成
B10: 法人マスタ | C10: 16法人の基本情報（コード、タイプ、スポンサー、決算期、投入状況）
B11: 物件マスタ | C11: 物件の基本情報（1物件1行）：所在地、延床面積、階数、竣工年月、取得価格、鑑定評価額、稼働率ほか
B12: 物件収支 | C12: 物件別の期次損益（1物件×1決算期で1行）：賃貸事業収入・費用の内訳、賃貸事業損益、NOI、NCF
B13: 比較ビュー | C13: 物件マスタ・物件収支・法人マスタを自動連結し、年換算NOI利回り・月坪賃料収入・費用率などの法人横断比較指標を数式で算出（全列自動計算・入力不要）
B15: 3. 単位・表記ルール（比較可能性の担保）
B16: 金額 | C16: 物件収支シート＝千円 ／ 取得価格・帳簿価額・鑑定評価額＝百万円 ／ 比較ビューの年換算NOI＝百万円
B17: 面積 | C17: ㎡で入力。坪換算は 1㎡=0.3025坪 で比較ビューが自動計算
B18: 比率 | C18: 稼働率・利回り等は小数で入力（例：97.5% → 0.975）。セル書式が%表示に変換
B19: 竣工年月・取得年月 | C19: 日付として入力（例：2005/3/1）。表示は「2005年03月」形式
B20: 決算期の表記 | C20: 「YYYY年M月期（第N期）」で統一。法人マスタと物件収支で完全一致させること（比較ビューのSUMIFSが文字列一致で参照するため）
B22: 4. 色の凡例
B23: 青字 | C23: 原資料から転記した手入力データ
B24: 黒字 | C24: 数式（編集しないこと）
B25: 黄色セル | C25: 要確認・要入力の項目
B26: 薄橙の行 | C26: 架空物件による記入例（実データ投入後に削除すること）
B28: 5. データ出典ルール（優先順位）
B29: ① | C29: 各投資法人の直近期「有価証券報告書」内「個別不動産の収支状況」→ 物件別の収入・費用内訳の一次情報
B30: ② | C30: 各投資法人の「資産運用報告」「決算短信」「決算説明資料」→ 物件基本情報・稼働率・鑑定評価額
B31: ③ | C31: 各投資法人ウェブサイトのポートフォリオページ → 建物概要の補完
B32: 非開示の扱い | C32: テナント同意が得られない物件は収支が非開示・一部非開示となる。開示区分列に「非開示」「一部非開示」と記録し、空欄と区別する。非開示物件を含む法人平均・合計を扱う際は注記必須。
B34: 6. 検証プロセス（各法人のデータ投入ごとに5段階を実施し、実施日を法人マスタ備考に記録）
B35: 第1段階：転記照合 | C35: 原資料PDFと全セルを突合（金額は千円単位まで一致確認）
B36: 第2段階：内訳整合 | C36: 物件収支の「内訳チェック」列が全行0、または0でない場合は備考欄で原資料由来の丸め差等として説明済みであることを確認（例：GOR-ALL行の差3千円は開示数値の丸めに由来）
B37: 第3段階：法人合計照合 | C37: 物件収支の法人別合計を、当該法人の損益計算書の賃貸事業収入・費用と突合（差異は非開示物件・期中売買物件として説明できること）
B38: 第4段階：指標妥当性 | C38: 比較ビューでNOI利回りが概ね2〜7%のレンジ外、稼働率100%超、月坪賃料が市場相場と乖離する物件を抽出し原資料へ立ち返って精査
B39: 第5段階：再計算検証 | C39: 全数式の再計算とエラー0件の確認、無作為抽出3物件の手計算照合
B41: 7. 現在の投入状況
B42: 法人マスタ | C42: 16法人投入済（決算期・期数に「要確認」フラグ付きの項目あり。黄色セル参照）
B43: 物件マスタ・物件収支 | C43: GOR（グローバル・ワン）投入済：物件18行（期末16物件＋期中譲渡1＋第46期取得1）＋ポートフォリオ全体行。物件別収支は収益・稼働率・テナント数まで開示、費用内訳は法人一括のみ（GOR-ALL行参照）。他15法人は順次投入。
A45: 【環境認証シート】(2026/8/7調査)
A46: ・各法人のウェブサイト/ESGレポート/決算説明資料/適時開示の公表情報に基づき、ZEB(BELS含む)/DBJ/CASBEE/LEED/WELLの5分類で物件別に収録。
A47: ・1物件が複数認証を保有する場合は複数行。同一物件の事務所/住宅/店舗別認証も別行(認証名称に区分を付記)。
A48: ・本シートに記載のない物件は、各法人の開示上、上記5分類の認証取得の公表が確認できなかった物件(=開示ベースで認証なし)。
...

Sheet 法人マスタ
A1: 法人ID | B1: 証券コード | C1: 投資法人名 | D1: 運用タイプ | E1: オフィス比率の目安 | F1: 主要スポンサー | G1: 決算月 | H1: 最新決算期（本DB収録対象） | I1: 保有物件数（直近開示） | J1: 取得価格合計(百万円) | K1: 物件データ投入数 | L1: 確認ステータス | M1: 備考
A2: NBF | B2: 8951 | C2: 日本ビルファンド投資法人 | D2: オフィス特化型 | E2: ほぼ100% | F2: 三井不動産・住友生命ほか | G2: 6月・12月 | H2: 2025年12月期（第49期） | I2: 70 | J2: 1519039 | K2: =COUNTIF(物件マスタ!$B:$B,$A2) -> 71 | L2: 確認済（短信照合） | M2: 決算月6月/12月。第49期短信より投入し5段階検証実施(2026/8/7)。※2026年6月期(第50期)短信は2026/8中旬公表見込み→公表後に差替検討。J-REIT最大規模・オフィス特化。格付JCR AA+/R&I AA/S&P A+。期末LTV43.3%・長期固定比率83.9%。収益開示59物件・非開示11物件(残差8,862百万円=一括比18.3%、取得価格比率19.2%と符合し整合確認済)。原資料の丸め表示に伴う合計欄と個別合算の微差は物件マスタNBF-ALL行注記参照
A3: JRE | B3: 8952 | C3: ジャパンリアルエステイト投資法人 | D3: オフィス特化型 | E3: ほぼ100% | F3: 三菱地所ほか | G3: 3月・9月 | H3: 2026年3月期（第49期） | I3: 79 | J3: 1197029 | K3: =COUNTIF(物件マスタ!$B:$B,$A3) -> 80 | L3: 確認済（短信照合） | M3: 日本初のJ-REIT2銘柄の一つ(2001/9上場・オフィス特化)。物件別収支は費用内訳までフル開示(76/79物件・百万円単位)。取得価格は千円単位開示でDB中最高精度。竣工年月は短信非掲載のため未収録。※第50期(2026年9月期)短信は2026/11中旬公表見込
A4: GOR | B4: 8958 | C4: グローバル・ワン不動産投資法人 | D4: オフィス特化型 | E4: ほぼ100% | F4: 明治安田生命・近鉄グループHD・三菱UFJ信託ほか | G4: 3月・9月 | H4: 2026年3月期（第45期） | I4: 17 | J4: 232273 | K4: =COUNTIF(物件マスタ!$B:$B,$A4) -> 19 | L4: 確認済（短信照合） | M4: 物件数・取得価格は2026/4/24現在（公式サイト）。物件・収支データは第45期短信より投入し5段階検証実施（2026/8/7）。物件収支の費用内訳は法人一括開示のみ（GOR-ALL行に収録）
A5: DOI | B5: 8976 | C5: 大和証券オフィス投資法人 | D5: オフィス特化型 | E5: ほぼ100% | F5: 大和証券グループ本社 | G5: 5月・11月 | H5: 2026年5月期（第41期） | I5: 58 | J5: 487709 | K5: =COUNTIF(物件マスタ!$B:$B,$A5) -> 61 | L5: 確認済（短信照合） | M5: 決算月5月/11月。物件・収支は第41期短信より投入し5段階検証実施(2026/8/7)。物件別収益は千円単位開示だが7物件はテナント同意なく非開示。竣工年月・階数は短信開示(登記簿ベース)。2026/12/1効力で投資口1:4分割・自己投資口取得(上限15億円)を公表。個別物件収支データ(Excel)を別途公表しており物件別費用の将来拡充が可能
A6: ICG | B6: 8975 | C6: いちごオフィスリート投資法人 | D6: オフィス主体型 | E6: 高 | F6: いちご | G6: 4月・10月 | H6: 2026年4月期（第41期） | I6: 87 | J6: 222508 | K6: =COUNTIF(物件マスタ!$B:$B,$A6) -> 89 | L6: 確認済（短信照合） | M6: 決算月4月/10月。第41期短信より投入し5段階検証実施(2026/8/7)。中規模オフィス特化型・87物件は16法人中最多クラスの小口分散。物件別に当期総賃料収入(その他収入含む発生ベース)をフル開示し88行合算が一括と整合(切捨て差42千円のみ)=MHRに次ぐ開示水準。ICG独自の地域区分(品川区含む「都心6区」等)は物件備考に保存。格付JCR A+。期末有利子負債126,638百万円。期後2026/7/17に4物件一括譲渡(住友商事・売却益約59億円)。※2026年10月期(第42期)短信は2026/12中旬公表見込→公表後更新検討
A7: JEI | B7: 8987 | C7: ジャパンエクセレント投資法人 | D7: オフィス特化型 | E7: ほぼ100% | F7: 日鉄興和不動産・第一生命・積水ハウスほか | G7: 6月・12月 | H7: 2025年12月期（第39期） | I7: 33 | J7: 290534 | K7: =COUNTIF(物件マスタ!$B:$B,$A7) -> 35 | L7: 確認済（短信照合） | M7: 2026年6月期は2026年8月下旬公表見込み（公表後に収録対象期の更新を検討）。物件・収支データは第39期短信より投入し5段階検証実施（2026/8/7）。物件別収益は千円単位開示だが8物件はテナント同意なく非開示
A8: MHR | B8: 3234 | C8: 森ヒルズリート投資法人 | D8: 総合型（オフィス中心） | E8: 約9割 | F8: 森ビル | G8: 1月・7月 | H8: 2026年1月期（第39期） | I8: 11 | J8: 416049 | K8: =COUNTIF(物件マスタ!$B:$B,$A8) -> 12 | L8: 確認済（短信照合） | M8: 決算月1月/7月。第39期短信より投入し5段階検証実施(2026/8/7)。16法人中初の物件別費用フル開示(11物件全て)。主要テナント森ビル(固定型ML中心、賃貸面積66.4%)。期後: ラフォーレ原宿底地各5%を2026/7・12に追加譲渡予定、自己投資口取得(上限10億円)実施済
A9: JPR | B9: 8955 | C9: 日本プライムリアルティ投資法人 | D9: 複合型（オフィス＋商業） | E9: 高 | F9: 東京建物ほか | G9: 6月・12月 | H9: 2025年12月期（第48期） | I9: 67 | J9: 556828 | K9: =COUNTIF(物件マスタ!$B:$B,$A9) -> 69 | L9: 確認済（短信照合） | M9: 決算月6月/12月。第48期短信(2026/3/10訂正=実績数値への影響なし)より投入し5段階検証実施(2026/8/7)。オフィス・都市型商業複合型(ホテル2物件含む)。JPR独自の地域区分(品川区含む「東京都心」等)は物件備考に保存。格付JCR AA/R&I AA-/S&P A(長期)。期末LTV43.4%・長期固定比率86.7%。開示51物件・非開示16物件(残差検証済)。期中譲渡HDC神戸を含め68行収録。取得価格合計欄と個別合算の1百万円差(切捨て由来)は物件マスタJPR-ALL行注記参照。2025/7/1投資口1:4分割
A10: TRE | B10: 8957 | C10: 東急リアル・エステート投資法人 | D10: 複合型（オフィス＋商業） | E10: 高 | F10: 東急 | G10: 1月・7月 | H10: 2026年1月期（第45期） | I10: 28 | J10: 244261 | K10: =COUNTIF(物件マスタ!$B:$B,$A10) -> 29 | L10: 確認済（短信照合） | M10: 決算月1月/7月。第45期短信より投入し5段階検証実施(2026/8/7)。渋谷・東急沿線特化型(商業・オフィス・住宅・複合)。物件別は帳簿・算定価額・契約賃料・PMLを開示する一方、取得価格・発生ベース収支は非開示という16法人中特異な開示スタイル(物件マスタ20・21・25列と備考に収録)。帳簿・月額賃料の合計欄と個別合算の各13千円差(切捨て由来)は物件マスタTRE-ALL行注記参照。格付JCR AA-/R&I A+。期末有利子負債1,055億円・加重平均利率0.82%。※2026年7月期(第46期)短信は2026/9/14公表予定→公表後更新検討
A11: HLC | B11: 3295 | C11: ヒューリックリート投資法人 | D11: 複合型（東京コマーシャル＋次世代アセット） | E11: 高 | F11: ヒューリック | G11: 2月・8月 | H11: 2026年2月期（第24期） | I11: 67 | J11: 421530 | K11: =COUNTIF(物件マスタ!$B:$B,$A11) -> 70 | L11: 確認済（短信照合） | M11: 東京コマーシャル・プロパティ(オフィス・商業)重点+ホテル+次世代アセット。取得価格は百万円未満四捨五入。物件別収支フル開示46/67物件(費用内訳含む・NOIのみ22物件)。期後NC5物件譲渡→62物件。※第25期(2026年8月期)短信は2026/10中旬公表見込
A12: NUD | B12: 8956 | C12: NTT都市開発リート投資法人 | D12: 複合型（オフィス＋住宅） | E12: 中〜高 | F12: NTT都市開発 | G12: 4月・10月 | H12: 2026年4月期（第47期） | I12: 62 | J12: 295266 | K12: =COUNTIF(物件マスタ!$B:$B,$A12) -> 64 | L12: 確認済（短信照合） | M12: 決算月4月/10月。第47期短信+公式ポートフォリオ一覧より投入し5段階検証実施(2026/8/7)。オフィス25+レジデンス36+優先出資証券1(秋葉原UDX19%)の複合型。物件別に費用内訳を含む損益をフル開示(百万円単位)=MHRに次ぐ第3の費用開示法人(非開示6物件は損益・NOIのみ開示、この2値の列解釈は用途計との突合で検証確定済)。NTTグループがテナント上位を占める(上位10テナント中8社・面積22.8%)。格付JCR AA。期末有利子負債147,250百万円(長期比率94.6%)。※2026年10月期(第48期)短信は2026/12中旬公表見込→公表後更新検討
A13: HFR | B13: 8966 | C13: 平和不動産リート投資法人 | D13: 複合型（オフィス＋住宅） | E13: 中 | F13: 平和不動産 | G13: 5月・11月 | H13: 2026年5月期（第49期） | I13: 136 | J13: 265046 | K13: =COUNTIF(物件マスタ!$B:$B,$A13) -> 139 | L13: 確認済（短信照合） | M13: 決算月5月/11月。第49期短信より投入し5段階検証実施(2026/8/7)。中小型オフィス46+レジデンス90の136物件複合型。物件別に鑑定・帳簿・取得・NLA・稼働・テナント数・賃貸事業収入(千円)・PMLを開示(Of-40アーク森ビルの収入のみML同意なく非開示)。竣工年月は短信非掲載。個別物件収支データ(費用内訳含む)はxlsx別綴で公表=将来精緻化候補。2010/10にジャパン・シングルレジデンス投資法人と合併。5年連続で毎年6月に公募増資を実施する成長軌道(期後2026/6も11,762百万円調達・3物件取得で139物件→8/7現在141物件)。格付JCR AA-(安定的)。期末有利子負債138,680百万円(総資産LTV48.55%)。※2026年11月期(第50期)短信は2027/1中旬公表見込→公表後更新検討
... A17: KDX | B17: 8972 | C17: ＫＤＸ不動産投資法人 | D17: 総合型 | E17: 中 | F17: ケネディクス | G17: 4月・10月 | H17: 2026年4月期（第42期） | I17: 343 | J17: 1218978 | K17: =COUNTIF(物件マスタ!$B:$B,$A17) -> 346 | L17: 確認済（短信照合） | M17: 決算月4月/10月。2023/11の3リート合併(旧KDXオフィス8972+ケネディクス・レジデンシャル・ネクスト3278+ケネディクス商業リート3453)で誕生した国内最大級総合型。第42期短信より投入(2026/8/7)。343物件・取得1,218,978百万円=16法人中最大。物件別開示は取得・帳簿・鑑定・NLA・稼働・テナント数・総賃貸事業収入(百万円単位)。所在地・竣工年月は短信非掲載(個別物件データブックxlsx別綴)→エリア区分は短信の東京経済圏/地方経済圏2区分を収録。物流14・宿泊6・ヘルスケア42の収入とアーク森ビルは非開示。規模が最大のため3応答分割で全343物件+譲渡2の投入完了・5段階検証実施(2026/8/7)。※第43期(2026年10月期)短信は2026/12中旬公表見込→公表後更新検討
A18: CTR | B18: 3488 | C18: セントラル・リート投資法人（旧ザイマックス・リート投資法人） | D18: 総合型（オフィス・商業・ホテル） | E18: 約56%（取得価格ベース） | F18: 名鉄都市開発・ザイマックスグループ（2025年10月よりダブルスポンサー） | G18: 2月・8月 | H18: 第16期（2026年2月期） | I18: 20 | J18: 50591 | K18: 20 | L18: 確認済（公式サイト・有報） | M18: 2025年11月の投資主総会承認によりザイマックス・リート投資法人から名称変更。2026年3月30日にエニシオ名駅・上前津KDビルを取得し20物件。第16期末の法人合計は稼働率99.9%・総賃貸可能面積86,030.38㎡・NOI 1,291百万円（半期）。平均稼働率は2026年6月30日現在99.6%
A19: ORI | B19: 3290 | C19: Oneリート投資法人 | D19: 総合型（中小規模オフィス中心） | E19: 約74%（取得価格ベース） | F19: みずほ信託銀行（みずほフィナンシャルグループ） | G19: 2月・8月 | H19: 第25期（2026年2月期） | I19: 34 | J19: 151202 | K19: 34 | L19: 確認済（公式サイト・決算短信） | M19: 2013年10月にSIA不動産投資法人として上場、2017年6月に現名称へ。2025年5月に用途を限定しない総合型へ規約変更しホテルへの投資を開始。中小規模オフィス（延床概ね33,000㎡未満）を重点投資対象とする。第25期末は28物件だが、2026年3月19日にホテル5物件とONEST飯田橋スクエアを取得し34物件（うちONEST京都烏丸スクエアは東京建物へ4回に分割して譲渡中、2026年3月に10%譲渡済で残90%）

Sheet 投資法人戦略
A1: 法人ID | B1: 投資法人名 | C1: 戦略ポジション | D1: 戦略の軸 | E1: モデルの構造 | F1: 主要リスク | G1: ESG・管理の特徴 | H1: 物件数 | I1: 資産規模(兆円・鑑定評価額ベース) | J1: 1物件平均(百万円・鑑定評価額ベース) | K1: 上位5物件集中度(%・鑑定評価額ベース) | L1: 粗利回り中央値(%・鑑定評価額ベース) | M1: 築年中央値 | N1: 稼働率中央値(%) | O1: 賃貸面積中央値(㎡) | P1: 東京圏比率(%) | Q1: 都心5区比率(%) | R1: オフィス比率(%) | S1: 用途構成 | T1: エリア構成 | U1: 認証保有率(%) | V1: 資産規模の算定物件数 | W1: 取得価格の開示率(%) | X1: 参考:取得価格合計(兆円) | Y1: 粗利回りの算定物件数 | Z1: 稼働率の算定物件数
A2: NBF | B2: 日本ビルファンド投資法人 | C2: 超大型コア・オフィス特化型 | D2: 規模の優位で「都心の象徴的資産」を押さえる | E2: 1物件あたり平均254億円（鑑定評価額ベース）はMHR(460億円)に次ぐ規模。三井不動産の開発物件を継続取得し、都心5区44%・東京圏74%に集中。オフィス100%で用途分散を放棄する代わり、テナント信用力と立地で下方リスクを抑える設計。 | F2: オフィス市況の一方向リスクを丸ごと負う。上位5物件で32.5%を占め、大型1棟の稼働変動が全体に効く。 | G2: 認証保有率97.1%は全法人最高。ESG適格性を資金調達コストと出口価格に転嫁する戦略が最も徹底している。 | H2: 70 | I2: 1.78 | J2: 25403 | K2: 32.5 | L2: 6.25 | N2: 100 | O2: 12481 | P2: 74.3 | Q2: 44.3 | R2: 100 | S2: オフィス100% | T2: 都心5区44% / 他23区19% / 他3大都市圏14% | U2: 97.1 | V2: 70 | W2: 100 | X2: 1.52 | Y2: 54 | Z2: 69
A3: JRE | B3: ジャパンリアルエステイト投資法人 | C3: 大型コア・オフィス特化型（全国分散併用） | D3: 都心の質と地方中核都市の利回りを両建てする | E3: 都心5区49%と最も都心比率が高い一方、地方圏19%を明示的に組み込む。1物件平均183億円。三菱地所の開発力を背景に、丸の内型のプライム物件と地方中核都市のランドマークを組み合わせ、キャップレート差を収益源にする。 | F3: 地方物件は流動性が低く、出口が限られる。テナント集中度の管理が生命線。 | G3: 認証91.1%。管理は三菱地所プロパティマネジメントに集約するが、物件名を非開示とする情報統制型。 | H3: 79 | I3: 1.45 | J3: 18320 | K3: 29.5 | L3: 5.74 | N3: 100 | O3: 7880 | P3: 67.1 | Q3: 49.4 | R3: 100 | S3: オフィス100% | T3: 都心5区49% / 地方圏19% / 他3大都市圏14% | U3: 91.1 | V3: 79 | W3: 100 | X3: 1.2 | Y3: 73 | Z3: 78
A4: GOR | B4: グローバル・ワン不動産投資法人 | C4: 少数精鋭・大型オフィス型 | D4: 18物件に絞り、1棟あたりの質で勝負する | E4: 保有18物件で1物件平均158億円。上位5物件で48.9%と集中度が高い。複数スポンサー（明治安田生命・近鉄・農林中金・三菱UFJ信託）の物件供給を受ける独立系に近い構造。粗利回り4.60%（鑑定評価額ベース）はMHR(4.44%)に次ぐ16法人で2番目の低さで、価格の高い優良物件を保有していることを示す。 | F4: 物件数が少なく、1棟の退去がポートフォリオ全体の稼働に直結する。スポンサー単独の開発パイプラインに依存できない。 | G4: 認証77.8%。規模の制約を質で補う典型。 | H4: 18 | I4: 0.25 | J4: 15788 | K4: 48.9 | L4: 4.6 | M4: 16.7 | N4: 100 | O4: 8890 | P4: 55.6 | Q4: 22.2 | R4: 100 | S4: オフィス100% | T4: 他3大都市圏33% / 都心5区22% / 他23区17% | U4: 77.8 | V4: 16 | W4: 94.4 | X4: 0.23 | Y4: 15 | Z4: 16
A5: DOI | B5: 大和証券オフィス投資法人 | C5: 都心集中・中規模オフィス型 | D5: 都心5区に83%を集中させ、立地だけで選別する | E5: 都心5区82.8%・東京圏98.3%は16法人で突出。1物件平均108億円・賃貸面積中央値3,794㎡と中規模に振り、築年中央値28.7年の既存ビルを取得してバリューアップする発想。 | F5: 築古比率が高く、修繕・設備更新の資本的支出が構造的に重い。エリア分散が事実上ないため、都心オフィス需給の変調を直撃で受ける。 | G5: 認証63.8%は都心特化型として低め。築古ストックへの認証後付けが今後の課題。 | H5: 58 | I5: 0.63 | J5: 10828 | K5: 34.3 | L5: 5.2 | M5: 28.7 | N5: 100 | O5: 3794 | P5: 98.3 | Q5: 82.8 | R5: 100 | S5: オフィス100% | T5: 都心5区83% / 他23区12% / 東京圏3% | U5: 63.8 | V5: 58 | W5: 96.7 | X5: 0.49 | Y5: 50 | Z5: 58
A6: ICG | B6: いちごオフィスリート投資法人 | C6: 中小型ビルの再生（バリューアッド）型 | D6: 市場に埋もれた中小ビルを買い、手を入れて価値を上げる | E6: 87物件・1物件平均33億円・賃貸面積中央値2,765㎡と小型の部類（HFR 2,078㎡・SHR 2,306㎡に次ぐ小ささ）。都心5区41%だが他23区25%・地方20%と広く拾う。大型プライム市場では価格競争に勝てないため、競合の少ない中小ビル市場で「心築（再生）」により利回りを作る。 | F6: 物件数が多く1棟あたりが小さいため、管理オペレーションの効率が収益を左右する。テナントは中小企業中心で信用力が相対的に低い。 | G6: 認証21.8%は最低水準。中小ビルは認証取得の費用対効果が出にくく、ESG評価では構造的に不利。 | H6: 87 | I6: 0.29 | J6: 3319 | K6: 14.9 | L6: 5.64 | N6: 100 | O6: 2765 | P6: 75.9 | Q6: 41.4 | R6: 97.7 | S6: オフィス98% / 商業2% | T6: 都心5区41% / 他23区25% / 他3大都市圏20% | U6: 21.8 | V6: 87 | W6: 0 | Y6: 87 | Z6: 87
A7: JEI | B7: ジャパンエクセレント投資法人 | C7: 大型オフィス・準コア型 | D7: 東京圏の大型物件を軸に、地方中核都市で利回りを補完 | E7: 33物件・1物件平均107億円。都心5区39%に対し東京圏21%・地方18%と分散。粗利回り7.06%（鑑定評価額ベース）は16法人で最高水準で、価格に対して収益の厚い物件を選好していることを示す。 | F7: 高利回りは市場が求めたリスクプレミアムでもある。地方大型物件の出口戦略が問われる。 | G7: 認証78.8%。日鉄興和不動産系の開発物件を受け皿とする構造。 | H7: 33 | I7: 0.35 | J7: 10655 | K7: 40 | L7: 7.06 | N7: 100 | O7: 6634 | P7: 69.7 | Q7: 39.4 | R7: 100 | S7: オフィス100% | T7: 都心5区39% / 東京圏21% / 地方圏18% | U7: 78.8 | V7: 33 | W7: 97.1 | X7: 0.29 | Y7: 25 | Z7: 33
A8: MHR | B8: 森ヒルズリート投資法人 | C8: 都心プレミアム集中型（最も極端な集中戦略） | D8: 森ビルの都心大規模再開発に100%張る | E8: 11物件すべてが都心5区。1物件平均460億円は16法人で最大、上位5物件で79.9%を占める。六本木ヒルズ・虎ノ門ヒルズ・アーク森ビルといった街区型再開発の持分を保有し、オフィス73%に住宅18%・商業9%を混ぜた複合用途で単一用途リスクを緩和。 | F8: 集中度79.9%は16法人で最高。1物件の稼働・賃料改定が分配金に直結する。全物件が都心5区かつ森ビルの開発物件であり、単一デベロッパーへの依存度が最も高い部類。 | G8: 粗利回り4.44%（鑑定評価額ベース）は最低水準。市場が最も低いキャップレートで評価している＝資産価値が最も高く評価されている裏返し。 | H8: 11 | I8: 0.51 | J8: 46000 | K8: 79.9 | L8: 4.44 | M8: 25.5 | N8: 100 | O8: 16153 | P8: 100 | Q8: 100 | R8: 72.7 | S8: オフィス73% / 住宅18% / 商業9% | T8: 都心5区100% | U8: 72.7 | V8: 11 | W8: 100 | X8: 0.42 | Y8: 10 | Z8: 11
A9: JPR | B9: 日本プライムリアルティ投資法人 | C9: オフィス＋商業のバランス型 | D9: 用途と地域の二軸で分散し、変動を平準化する | E9: オフィス75%・商業22%。都心5区45%に東京圏21%を組み合わせ、上位5物件の集中度30.8%は低位。1物件平均100億円。東京建物の開発物件を軸にしつつ、特定用途・特定物件への依存を意図的に避けた設計。 | F9: 分散は変動を抑える一方で突出した成長も生みにくい。商業施設は個別のテナント業績に業績が連動する。 | G9: 築年中央値30.1年と築古。認証71.6%。計画修繕の巧拙が長期のNOIを決める帯にある。 | H9: 67 | I9: 0.67 | J9: 10015 | K9: 30.8 | L9: 6.12 | M9: 30.1 | N9: 100 | O9: 5185 | P9: 77.6 | Q9: 44.8 | R9: 74.6 | S9: オフィス75% / 商業22% / ホテル3% | T9: 都心5区45% / 東京圏21% / 他23区12% | U9: 71.6 | V9: 67 | W9: 98.5 | X9: 0.56 | Y9: 50 | Z9: 67
A10: TRE | B10: 東急リアル・エステート投資法人 | C10: 沿線集中・複合用途型 | D10: 東急沿線という「面」に投資し、街の成長を取り込む | E10: 28物件すべてが東京圏、都心5区71%。1物件平均117億円。オフィス64%・商業21%・住宅11%の複合。渋谷・二子玉川など東急が開発を主導するエリアに集中し、街づくりの果実を賃料成長として回収する構造。 | F10: 沿線集中は地域経済の変調に対する分散が効かない。築年中央値31.4年と築古で、更新投資の負担が重い。 | G10: LEED ND（まちづくり部門）を取得した二子玉川ライズを保有。街区単位でのESG評価という他法人にない資産を持つ。 | H10: 28 | I10: 0.33 | J10: 11676 | K10: 43.5 | M10: 31.4 | N10: 100 | O10: 4616 | P10: 100 | Q10: 71.4 | R10: 64.3 | S10: オフィス64% / 商業21% / 住宅11% | T10: 都心5区71% / 他23区21% / 東京圏7% | U10: 75 | V10: 28 | W10: 0 | Y10: 0 | Z10: 28
A11: HLC | B11: ヒューリックリート投資法人 | C11: 用途分散・駅前立地特化型 | D11: 駅前という立地条件を共通項に、用途を跨いで分散する | E11: オフィス51%・ヘルスケア21%・商業12%。東京圏92.5%だが他23区45%が都心5区40%を上回る。1物件平均73億円。ヒューリックの「駅前・駅近」戦略を継承し、用途ではなく立地で選別する点が他法人と決定的に異なる。ヘルスケア21%は高齢化を捉えた長期契約型キャッシュフロー。 | F11: ヘルスケアはオペレーター信用力に依存し、代替が難しい。用途分散はモニタリング負荷を高める。 | G11: 管理をヒューリックビルマネジメントに内製集約。グループ内で運営品質を統制する垂直統合型。 | H11: 67 | I11: 0.49 | J11: 7259 | K11: 34.6 | L11: 5.48 | M11: 21.2 | N11: 100 | O11: 3957 | P11: 92.5 | Q11: 40.3 | R11: 50.7 | S11: オフィス51% / ヘルスケア21% / 商業12% | T11: 他23区45% / 都心5区40% / 東京圏7% | U11: 41.8 | V11: 67 | W11: 97.1 | X11: 0.42 | Y11: 44 | Z11: 67
A12: NUD | B12: NTT都市開発リート投資法人 | C12: 住宅・オフィス二本柱型 | D12: 変動の大きいオフィスを、安定的な住宅で中和する | E12: 住宅58%・オフィス40%。都心5区56.5%と都心比率は高い。1物件平均55億円と中規模。オフィスの景気連動性を、賃料変動の小さい都心住宅で打ち消すポートフォリオ設計。 | F12: 住宅は個別の賃料上昇余地が限られ、成長エンジンにはなりにくい。稼働率中央値99.2%と既に高位で、稼働改善の余地が乏しい。 | G12: 認証71.0%。住宅系でのDBJ認証取得（23件）を積極化しており、オフィス偏重になりがちな認証取得を住宅にも広げている点が特徴。 | H12: 62 | I12: 0.34 | J12: 5497 | K12: 31.5 | L12: 5.3 | N12: 99.2 | P12: 88.7 | Q12: 56.5 | R12: 40.3 | S12: 住宅58% / オフィス40% / その他2% | T12: 都心5区56% / 他23区31% / 他3大都市圏8% | U12: 71 | V12: 61 | W12: 98.4 | X12: 0.3 | Y12: 52 | Z12: 61
A13: HFR | B13: 平和不動産リート投資法人 | C13: 小口分散・住宅主体型 | D13: 小さく多く持ち、1棟の失敗が効かない構造をつくる | E13: 136物件・1物件平均24億円は16法人で最小。上位5物件の集中度11.9%も最小で、極端な分散型。住宅66%・オフィス34%、他23区38%と都心外の実需エリアが中心。 | F13: 1棟あたりが小さいため管理コストの比率が上がりやすい。物件数の多さは運営負荷とデータ管理の難易度を高める。 | G13: 認証22.8%と低位。小規模物件は認証取得の採算が合わず、ESG面では構造的な制約を抱える。 | H13: 136 | I13: 0.33 | J13: 2436 | K13: 11.9 | L13: 5.41 | N13: 99.25 | O13: 2078 | P13: 70.6 | Q13: 22.8 | R13: 33.8 | S13: 住宅66% / オフィス34% | T13: 他23区38% / 都心5区23% / 他3大都市圏15% | U13: 22.8 | V13: 136 | W13: 98.6 | X13: 0.27 | Y13: 135 | Z13: 136
A14: SHR | B14: 積水ハウス・リート投資法人 | C14: 住宅特化・スポンサー開発直結型 | D14: 積水ハウスの開発供給を受け皿として安定成長する | E14: 住宅96%。他23区46%・都心5区18%と、都心よりも実需の厚いエリアに展開。1物件平均48億円。築年中央値16.8年と16法人で最も築浅で、スポンサーの新築供給を継続的に取得している証左。米国物件も保有し地理分散を試行。 | F14: 稼働率中央値96.4%は16法人で最低。住宅は入退去が常態で、稼働の底上げ余地が最大の改善テーマ。 | G14: 認証81.2%と住宅系では突出。CASBEE不動産103件・BELS★5×9件で、ZEH水準の新築供給がそのまま認証率に直結している。 | H14: 138 | I14: 0.67 | J14: 4823 | K14: 36.9 | L14: 4.83 | M14: 16.8 | N14: 96.4 | O14: 2306 | P14: 78.3 | Q14: 18.1 | R14: 3.6 | S14: 住宅96% / オフィス4% | T14: 他23区46% / 都心5区18% / 東京圏14% | U14: 81.2 | V14: 138 | W14: 92 | X14: 0.56 | Y14: 136 | Z14: 138
A15: MTR | B15: 森トラストリート投資法人 | C15: 大型・複合（オフィス＋ホテル）型 | D15: オフィスの安定とホテルの変動を意図的に組み合わせる | E15: 20物件・1物件平均268億円と大型。オフィス50%・ホテル30%・商業15%。上位5物件で57.3%と集中度が高い。森トラストの大型開発とホテル運営力を背景に、景気拡大局面ではホテルが伸び、後退局面ではオフィスが支える設計。 | F15: ホテルは変動費型で業績連動性が高く、外的ショックに脆い。集中度の高さがそれを増幅する。 | G15: 認証95.0%は最高水準。DBJ18件で、評価語（国内トップクラス等）ベースの高位認証を多数保有。 | H15: 20 | I15: 0.54 | J15: 26821 | K15: 57.3 | L15: 5.09 | M15: 27.4 | N15: 100 | O15: 20952 | P15: 75 | Q15: 45 | R15: 50 | S15: オフィス50% / ホテル30% / 商業15% | T15: 都心5区45% / 東京圏20% / 他3大都市圏15% | U15: 95 | V15: 20 | W15: 100 | X15: 0.46 | Y15: 18 | Z15: 20
A16: SKR | B16: サンケイリアルエステート投資法人 | C16: 総合型への転換途上 | D16: オフィス単独から用途分散へ舵を切っている最中 | E16: 16物件・オフィス56%・ホテル38%・物流6%。築年中央値8.85年と16法人で最も築浅。2023年に運用ガイドラインを変更し総合型REITへ転換しており、現在のポートフォリオは移行途上の姿。 | F16: 規模が小さく上位5物件で51.1%を占める。2026年に非公開化を目的としたTOBが実施され不成立に終わっており、資本政策の不確実性を抱える。 | G16: 認証25.0%と低位。ただし築浅比率が高く、今後の認証取得余地は大きい。 | H16: 16 | I16: 0.1 | J16: 6041 | K16: 51.1 | M16: 8.85 | N16: 100 | O16: 5386 | P16: 56.2 | Q16: 37.5 | R16: 56.2 | S16: オフィス56% / ホテル38% / 物流6% | T16: 都心5区38% / 地方圏25% / 他3大都市圏19% | U16: 25 | V16: 16 | W16: 100 | X16: 0.09 | Y16: 0 | Z16: 16
A17: KDX | B17: ＫＤＸ不動産投資法人 | C17: 超分散・独立系マルチアセット型 | D17: スポンサー系列に依存せず、市場から広く買い集める | E17: 343物件は16法人で最多、1物件平均39億円・上位5物件の集中度9.0%は最小。住宅39%・オフィス25%・商業17%と用途を広く分散し、東京圏68%・地方圏32%。特定の開発会社の供給に依存せず、市場全体を調達源とする独立系の典型。 | F17: 物件数の多さは管理・情報開示の負荷を高める。分散は下振れを抑えるが、個別物件のバリューアップ効果は薄まる。 | G17: 管理をケネディクス・プロパティ・デザインに集約し、183棟を実名公開。16法人で最も管理体制の透明性が高い。 | H17: 343 | I17: 1.34 | J17: 3913 | K17: 9 | L17: 5.33 | N17: 100 | O17: 3534 | P17: 67.9 | Q17: 0 | R17: 25.1 | S17: 住宅39% / オフィス25% / 商業17% | T17: 東京圏68% / 地方圏32% | U17: 56.6 | V17: 343 | W17: 99.4 | X17: 1.22 | Y17: 243 | Z17: 343
A18: CTR | B18: セントラル・リート投資法人 | C18: 小型総合型・中部圏シフト途上 | D18: PM実績を持つスポンサーの運営力で中小型物件の収益を引き上げる | E18: 20物件・1物件平均32億円と16法人中で最小の部類。オフィス55%・商業30%・ホテル10%の総合型で、都心5区25%・他3大都市圏35%と地方分散が進む。スポンサーのザイマックスはJ-REITのPM受託で実績首位であり、自ら運営する物件を組み入れることで、中小型ビルでも管理品質を担保する構造。2025年10月に名鉄都市開発が51%を取得しダブルスポンサー体制へ移行、2026年3月に名古屋の2物件を取得し中部圏へのシフトを開始した。 | F18: 資産規模506億円は16法人で最小級で、1物件の稼働変動が分配金に直結する。オフィス・商業・ホテル・住宅と用途が分散する一方、各用途の物件数が少なく用途別の運営ノウハウの蓄積が限定的。スポンサー交代に伴う投資方針の変化も不確実性となる。 | G18: 認証取得は12物件・延床面積ベース76.1%。CASBEE不動産8物件（うちSランク7）とBELS4物件を保有し、エニシオ名駅はBELS★5。保有オフィス9物件すべてで再生可能エネルギー100%電力を導入。GRESBリアルエステイト評価で4スター・グリーンスター、開示評価はAレベル。 | H18: 20 | I18: 0.06 | J18: 3231 | K18: 46.7 | M18: 26.4 | P18: 65 | Q18: 25 | R18: 55 | S18: オフィス55% / 商業30% / ホテル10% | T18: 他3大都市圏35% / 都心5区25% / 東京圏25% | U18: 60 | V18: 20 | W18: 100 | X18: 0.05 | Y18: 0 | Z18: 0
A19: ORI | B19: Oneリート投資法人 | C19: 中小型オフィス特化からホテル併走型への転換途上 | D19: みずほの情報網で中小型ビルを仕入れ、運営改善で価値を引き上げる | E19: 34物件・1物件平均51億円。延床概ね33,000㎡未満の中小規模オフィスを重点対象とし、都心5区は17.6%と低く、その他23区・東京周辺都市部・地方中核市に分散する。2025年5月に用途無限定の総合型へ規約変更し、2026年3月にホテル5物件（286億円）を一括取得してホテル比率を約25%へ引き上げた。物件入替を継続的に行い、2025年以降だけで南品川3物件・MY熊本・ONEST南大塚・新川一丁目を売却、京都烏丸スクエアも東京建物へ4回分割で譲渡中。中長期の資産規模目標は2,000億円。 | F19: 中小型ビルは大企業の集約移転の受け皿になりにくく、テナント数が多いぶん個別の退去が積み上がりやすい。築年中央値34.5年と16法人で最も古い部類にあり、資本的支出が重い（第25期は533百万円で修繕費131百万円と合わせ664百万円）。ホテルへの急速な傾斜は収益の変動性を高める可能性があり、運営ノウハウの蓄積も途上。 | G19: 認証取得は25物件（CASBEE不動産21件・DBJ Green Building 3件・BELS 2件）。CASBEEはAランクが18件と中心で、Sランクは立川錦町ビルと大同生命水戸ビルの2件。ONEST箱崎ビルはBELS6つ星。延床面積ベースのグリーンビル認証取得割合を2030年度に90%とするKPIを掲げる。GRESBリアルエステイト評価で4スター・Green Starを8年連続獲得。 | H19: 34 | I19: 0.17 | J19: 5081 | K19: 32 | M19: 34.5 | N19: 100 | O19: 4200 | P19: 61.8 | Q19: 17.6 | R19: 79.4 | S19: オフィス79% / ホテル21% | T19: その他23区24% / 東京周辺都市部21% / その他3大都市圏21% / 都心5区18% / 政令市12% / 地方6% | U19: 73.5 | V19: 34 | W19: 100 | X19: 0.15 | Z19: 28

Sheet 物件マスタ
A1: 物件ID | B1: 法人ID | C1: 物件名 | D1: 主用途 | E1: 都道府県 | F1: 市区町村 | G1: 住所（詳細） | H1: エリア区分 | I1: 所有形態 | J1: 持分割合 | K1: 敷地面積(㎡) | L1: 延床面積(㎡) | M1: 賃貸可能面積(㎡) | N1: 階数(地上) | O1: 階数(地下) | P1: 竣工年月 | Q1: 築年数(年) | R1: 取得年月 | S1: 取得価格(百万円) | T1: 期末帳簿価額(百万円) | U1: 期末鑑定評価額(百万円) | V1: 含み損益(百万円) | W1: 期末稼働率 | X1: テナント数 | Y1: PML(%) | Z1: 出典（資料名・頁） | AA1: 確認ステータス | AB1: 備考 | AC1: 環境認証数 | AD1: 含み損益率(%)＝鑑定÷帳簿−1 | AE1: 対取得価格の値上がり率(%)＝鑑定÷取得−1
A2: NBF-ALL | B2: NBF | C2: 【NBFポートフォリオ全体】 | D2: オフィス | E2: 東京都 | F2: 千代田区 | H2: ─ | I2: 70物件（2025/12/31時点） | L2: 51094.82 | M2: 1239418 | P2: 40148 | Q2: =IF(OR($A199="",P199=""),"",ROUND(YEARFRAC(P199,README!$C$5),1)) -> 24.9 | S2: 1519039 | T2: 1411111 | U2: 1778190 | V2: =IF($A199="","",IF(OR(T199="",U199=""),"",U199-T199)) -> 1869 | W2: 0.983 | X2: 1584 | Y2: 2.9 | Z2: NBF 2025年12月期(第49期)決算短信(2026/2/16公表) | AA2: 確認済※ | AB2: J-REIT最大規模(取得価格累計1兆5,190億円)。取得・帳簿・鑑定は千円開示を百万円換算(小数3位=千円精度)。本行は短信合計欄の値。【原資料の丸め表示に関する注記】帳簿価額は円単位の値を千円未満切捨て表示のため、70物件個別値の合算(1,411,110,984千円)は合計欄より35千円小(各地域小計の差-16/-6/-3/-9千円も全て負符号で物件数以内=切捨て累積として整合的)。取得価格も按分物件の円未満端数により総計欄と-1千円差(地域小計は完全一致)。NLAは個別値の小数点以下四捨五入により合計欄と1㎡差。鑑定・テナント数は完全一致。期末稼働98.3%/期中平均98.5%。NLA・テナント数にNBF虎ノ門ビル(底地)は含まず。最大テナント三井不動産(賃貸面積47.0%・サブリース転貸方式24物件)。期後: 2026/1公募増資等(発行済8,815,000口へ)、2026/3/31日本橋本町M-SQUARE(32,108百万円)・豊洲ベイサイドクロスタワー追加持分(14,810百万円)取得予定、2026/6/30住友電設ビル・2026/7/1 NBF札幌南二条ビル譲渡予定 | AC2: =COUNTIF(環境認証!$A$2:$A$849,A199) -> 1 | AD2: 42.4 | AE2: 29.7
A3: NBF-01 | B3: NBF | C3: 新宿三井ビルディング | D3: オフィス | E3: 東京都 | F3: 新宿区 | H3: 都心5区 | I3: 所有権（信託受益権準共有80%） | J3: 0.8 | L3: 20958.79 | M3: 102718 | P3: 37742 | Q3: =IF(OR($A129="",P129=""),"",ROUND(YEARFRAC(P129,README!$C$5),1)) | S3: 170000 | T3: 175537.94 | U3: 184000 | V3: 8462 | W3: 0.984 | X3: 100 | Y3: 2.8 | Z3: NBF 2025年12月期(第49期)決算短信(2026/2/16公表) | AA3: 確認済 | AB3: オフィス。竣工年月・階数・面積は短信非掲載(有報等で補完予定)。J-REIT運用資産中最大の旗艦物件。サブリース型(変動賃料) | AC3: =COUNTIF(環境認証!$A$2:$A$849,A129) -> 1 | AD3: 4.8 | AE3: 8.2
A4: NBF-02 | B4: NBF | C4: 飯田橋グラン・ブルーム | D4: オフィス | E4: 東京都 | F4: 千代田区 | H4: 都心5区 | I4: 区分所有権（信託受益権） | L4: 140667.09 | M4: 54185 | P4: 41122 | Q4: =IF(OR($A130="",P130=""),"",ROUND(YEARFRAC(P130,README!$C$5),1)) | S4: 138909.1 | T4: 135524 | U4: 154000 | V4: 18476 | W4: 1 | X4: 34 | Y4: 0.3 | Z4: NBF 2025年12月期(第49期)決算短信(2026/2/16公表) | AA4: 確認済 | AB4: オフィス。竣工年月・階数・面積は短信非掲載(有報等で補完予定)。2021/9・2022/3・2023/3の3回取得合計。サブリース型(変動) | AC4: =COUNTIF(環境認証!$A$2:$A$849,A130) -> 1 | AD4: 13.6 | AE4: 10.9
A5: NBF-03 | B5: NBF | C5: 六本木ティーキューブ | D5: オフィス | E5: 東京都 | F5: 港区 | H5: 都心5区 | I5: 区分所有権（信託受益権） | L5: 15467.77 | M5: 34608 | P5: 40179 | Q5: =IF(OR($A131="",P131=""),"",ROUND(YEARFRAC(P131,README!$C$5),1)) | S5: 62800 | T5: 62129.469 | U5: 63200 | V5: 1071 | W5: 0.965 | X5: 65 | Y5: 1.8 | Z5: NBF 2025年12月期(第49期)決算短信(2026/2/16公表) | AA5: 確認済 | AB5: オフィス。竣工年月・階数・面積は短信非掲載(有報等で補完予定)。サブリース型(変動) | AC5: =COUNTIF(環境認証!$A$2:$A$849,A131) -> 2 | AD5: 1.7 | AE5: 0.6
A6: NBF-04 | B6: NBF | C6: 西新宿三井ビルディング | D6: オフィス | E6: 東京都 | F6: 新宿区 | H6: 都心5区 | I6: 所有権（信託受益権準共有50%） | J6: 0.5 | L6: 41741.18 | M6: 33770 | P6: 40391 | Q6: =IF(OR($A132="",P132=""),"",ROUND(YEARFRAC(P132,README!$C$5),1)) | S6: 45392.204 | T6: 31915.468 | U6: 46100 | V6: 14185 | W6: 0.997 | X6: 52 | Y6: 7 | Z6: NBF 2025年12月期(第49期)決算短信(2026/2/16公表) | AA6: 確認済 | AB6: オフィス。竣工年月・階数・面積は短信非掲載(有報等で補完予定)。任意組合出資持分(西新宿六丁目共有組合)含む。2002〜2023年の8回分割取得合計。サブリース型(変動) | AC6: =COUNTIF(環境認証!$A$2:$A$849,A132) -> 1 | AD6: 44.4 | AE6: 1.6
A7: NBF-05 | B7: NBF | C7: セレスティン芝三井ビルディング | D7: オフィス | E7: 東京都 | F7: 港区 | G7: 横浜市神奈川区金港町2-6 | H7: 都心5区 | I7: 所有権（信託受益権準共有）※期末60% | J7: 0.6 | K7: 2720.3 | L7: 19968.2 | M7: 38011 | P7: 40210 | Q7: =IF(OR($A133="",P133=""),"",ROUND(YEARFRAC(P133,README!$C$5),1)) | S7: 42000 | T7: 41134.739 | U7: 47200 | V7: 6065 | W7: 1 | X7: 11 | Z7: NBF 2025年12月期(第49期)決算短信(2026/2/16公表) | AA7: 確認済 | AB7: オフィス。竣工年月・階数・面積は短信非掲載(有報等で補完予定)。2013/5・2018/3の取得合計。ホテル部分は固定賃料契約 | AC7: =COUNTIF(環境認証!$A$2:$A$849,A133) -> 1 | AD7: 14.7 | AE7: 12.4
A8: NBF-06 | B8: NBF | C8: ＮＢＦ品川タワー | D8: オフィス | E8: 東京都 | F8: 港区 | H8: 都心5区 | I8: 所有権 共有持分50%（信託受益権） | J8: 0.5 | L8: 78897.42 | M8: 22778 | P8: 37316 | Q8: =IF(OR($A134="",P134=""),"",ROUND(YEARFRAC(P134,README!$C$5),1)) | S8: 36300 | T8: 37303.912 | U8: 47700 | V8: 10396 | W8: 0.997 | X8: 11 | Y8: 2.8 | Z8: NBF 2025年12月期(第49期)決算短信(2026/2/16公表) | AA8: 確認済 | AB8: オフィス。竣工年月・階数・面積は短信非掲載(有報等で補完予定)。主要テナント:楽天グループ | AC8: =COUNTIF(環境認証!$A$2:$A$849,A134) -> 1 | AD8: 27.9 | AE8: 31.4
A9: NBF-07 | B9: NBF | C9: ＮＢＦプラチナタワー | D9: オフィス | E9: 東京都 | F9: 港区 | G9: 千葉市中央区富士見2-5-12 | H9: 都心5区 | I9: 所有権（信託受益権） | J9: 1 | K9: 2487.92 | L9: 14201.97 | M9: 33503 | N9: 11 | O9: 0 | P9: 44927 | Q9: =IF(OR($A135="",P135=""),"",ROUND(YEARFRAC(P135,README!$C$5),1)) | R9: 46111 | S9: 31000 | T9: 25321.171 | U9: 60800 | V9: 35479 | W9: 0.981 | X9: 8 | Y9: 9.2 | Z9: NBF 2025年12月期(第49期)決算短信(2026/2/16公表) | AA9: 確認済 | AB9: オフィス。竣工年月・階数・面積は短信非掲載(有報等で補完予定)。鑑定評価額60,800百万円は取得価格の約2倍。主要テナント:アクサ生命 | AC9: =COUNTIF(環境認証!$A$2:$A$849,A135) -> 1 | AD9: 140.1 | AE9: 96.1
A10: NBF-08 | B10: NBF | C10: ＮＢＦコモディオ汐留 | D10: オフィス | E10: 東京都 | F10: 港区 | H10: 都心5区 | I10: 所有権（信託受益権） | J10: 1 | L10: 23161.27 | M10: 20538 | P10: 34759 | Q10: =IF(OR($A136="",P136=""),"",ROUND(YEARFRAC(P136,README!$C$5),1)) | S10: 28800 | T10: 27591.934 | U10: 35800 | V10: 8208 | W10: 1 | X10: 22 | Y10: 9.9 | Z10: NBF 2025年12月期(第49期)決算短信(2026/2/16公表) | AA10: 確認済 | AB10: オフィス。竣工年月・階数・面積は短信非掲載(有報等で補完予定)。 | AC10: =COUNTIF(環境認証!$A$2:$A$849,A136) -> 2 | AD10: 29.7 | AE10: 24.3
A11: NBF-09 | B11: NBF | C11: Ｇ－ＢＡＳＥ田町 | D11: オフィス | E11: 東京都 | F11: 港区 | H11: 都心5区 | I11: 所有権（共有持分20%） | J11: 0.2 | L11: 35198.77 | M11: 12481 | P11: 39995 | Q11: =IF(OR($A137="",P137=""),"",ROUND(YEARFRAC(P137,README!$C$5),1)) | S11: 28200 | T11: 26674.626 | U11: 29100 | V11: 2425 | W11: 1 | X11: 13 | Y11: 1.9 | Z11: NBF 2025年12月期(第49期)決算短信(2026/2/16公表) | AA11: 確認済 | AB11: オフィス。竣工年月・階数・面積は短信非掲載(有報等で補完予定)。2019年3・4月の取得合計 | AC11: =COUNTIF(環境認証!$A$2:$A$849,A137) -> 1 | AD11: 9.1 | AE11: 3.2
A12: NBF-10 | B12: NBF | C12: 虎ノ門琴平タワー | D12: オフィス | E12: 東京都 | F12: 港区 | G12: 大阪市東淀川区東中島1-19-4 | H12: 都心5区 | I12: 所有権（信託受益権） | J12: 1 | K12: 2034.62 | L12: 9383.85 | M12: 16848 | N12: 12 | O12: 0 | P12: 33178 | Q12: =IF(OR($A138="",P138=""),"",ROUND(YEARFRAC(P138,README!$C$5),1)) | R12: 45996 | S12: 24543 | T12: 17026 | U12: 34300 | V12: 17274 | W12: 0.988 | X12: 26 | Y12: 7.2 | Z12: NBF 2025年12月期(第49期)決算短信(2026/2/16公表) | AA12: 確認済 | AB12: オフィス。竣工年月・階数・面積は短信非掲載(有報等で補完予定)。敷地の賃借権を含む。2004/11・2006/4の取得合計。サブリース型(変動) | AC12: =COUNTIF(環境認証!$A$2:$A$849,A138) -> 2 | AD12: 101.5 | AE12: 39.8
A13: NBF-11 | B13: NBF | C13: ＮＢＦ渋谷ガーデンフロント | D13: オフィス | E13: 東京都 | F13: 渋谷区 | H13: 都心5区 | I13: 所有権（共有持分5%） | J13: 0.05 | L13: 75826.76 | M13: 14887 | P13: 42064 | Q13: =IF(OR($A139="",P139=""),"",ROUND(YEARFRAC(P139,README!$C$5),1)) | S13: 20269 | T13: 19878.48 | U13: 37200 | V13: 17322 | W13: 0.999 | X13: 4 | Y13: 0.8 | Z13: NBF 2025年12月期(第49期)決算短信(2026/2/16公表) | AA13: 確認済 | AB13: オフィス。竣工年月・階数・面積は短信非掲載(有報等で補完予定)。2004/2・2013/3の取得合計。主要テナント:インフィニオンテクノロジーズジャパン | AC13: =COUNTIF(環境認証!$A$2:$A$849,A139) -> 1 | AD13: 87.1 | AE13: 83.5
A14: NBF-12 | B14: NBF | C14: ＮＢＦ銀座通りビル | D14: オフィス | E14: 東京都 | F14: 中央区 | G14: 大阪市北区梅田3-3-20 | H14: 都心5区 | I14: 所有権（信託受益権準共有）※期末28% | J14: 0.28 | K14: 5999.33 | L14: 52982.94 | M14: 3440 | N14: 31 | O14: 2 | P14: 36678 | Q14: =IF(OR($A140="",P140=""),"",ROUND(YEARFRAC(P140,README!$C$5),1)) | R14: 45772 | S14: 17000 | T14: 17425.076 | U14: 19000 | V14: 1575 | W14: 1 | X14: 1 | Y14: 0.5 | Z14: NBF 2025年12月期(第49期)決算短信(2026/2/16公表) | AA14: 確認済 | AB14: オフィス。竣工年月・階数・面積は短信非掲載(有報等で補完予定)。地上権を含む | AC14: =COUNTIF(環境認証!$A$2:$A$849,A140) -> 2 | AD14: 9 | AE14: 11.8
A15: NBF-13 | B15: NBF | C15: 新宿三井ビルディング二号館 | D15: オフィス | E15: 東京都 | F15: 新宿区 | H15: 都心5区 | I15: 所有権（共有持分50%） | J15: 0.5 | L15: 32997.6 | M15: 14617 | P15: 37073 | Q15: =IF(OR($A141="",P141=""),"",ROUND(YEARFRAC(P141,README!$C$5),1)) | S15: 16285.4 | T15: 15775.462 | U15: 19600 | V15: 3825 | W15: 1 | X15: 44 | Y15: 0.5 | Z15: NBF 2025年12月期(第49期)決算短信(2026/2/16公表) | AA15: 確認済 | AB15: オフィス。竣工年月・階数・面積は短信非掲載(有報等で補完予定)。 | AC15: =COUNTIF(環境認証!$A$2:$A$849,A141) -> 0 | AD15: 24.2 | AE15: 20.4
A16: NBF-14 | B16: NBF | C16: 興和西新橋ビルＢ棟 | D16: オフィス | E16: 東京都 | F16: 港区 | G16: 福岡市博多区中洲中島町1-3 | H16: 都心5区 | I16: 所有権（信託受益権準共有83%） | J16: 0.83 | K16: 2064.27 | L16: 15647.62 | M16: 10405 | N16: 14 | O16: 0 | P16: 45078 | Q16: =IF(OR($A142="",P142=""),"",ROUND(YEARFRAC(P142,README!$C$5),1)) | R16: 45968 | S16: 13536.2 | T16: 11710.476 | U16: 13400 | V16: 1690 | W16: 0.989 | X16: 22 | Y16: 0.2 | Z16: NBF 2025年12月期(第49期)決算短信(2026/2/16公表) | AA16: 確認済 | AB16: オフィス。竣工年月・階数・面積は短信非掲載(有報等で補完予定)。2001〜2024年の5回分割取得合計。住宅部分はサブリース(変動) | AC16: =COUNTIF(環境認証!$A$2:$A$849,A142) -> 2 | AD16: 14.4 | AE16: -1
A17: NBF-15 | B17: NBF | C17: リバーシティＭ－ＳＱＵＡＲＥ | D17: オフィス | E17: 東京都 | F17: 中央区 | H17: 都心5区 | I17: 所有権（信託受益権） | J17: 1 | L17: 12823.15 | M17: 16261 | P17: 44348 | Q17: =IF(OR($A143="",P143=""),"",ROUND(YEARFRAC(P143,README!$C$5),1)) | S17: 13350 | T17: 11167.859 | U17: 13500 | V17: 2332 | W17: 1 | X17: 7 | Y17: 0.3 | Z17: NBF 2025年12月期(第49期)決算短信(2026/2/16公表) | AA17: 確認済 | AB17: オフィス。竣工年月・階数・面積は短信非掲載(有報等で補完予定)。 | AC17: =COUNTIF(環境認証!$A$2:$A$849,A143) -> 1 | AD17: 20.9 | AE17: 1.1
A18: NBF-16 | B18: NBF | C18: 新橋Ｍ－ＳＱＵＡＲＥ | D18: オフィス | E18: 東京都 | F18: 港区 | G18: 墨田区錦糸1-2-1 | H18: 都心5区 | I18: （期中譲渡済） | J18: 0 | K18: 18100.41 | L18: 49753.92 | M18: 5390 | Q18: =IF(OR($A144="",P144=""),"",ROUND(YEARFRAC(P144,README!$C$5),1)) | S18: 11900 | T18: 11061.277 | U18: 15100 | V18: 4039 | W18: 1 | X18: 10 | Z18: NBF 2025年12月期(第49期)決算短信(2026/2/16公表) | AA18: 確認済 | AB18: オフィス。竣工年月・階数・面積は短信非掲載(有報等で補完予定)。 | AC18: =COUNTIF(環境認証!$A$2:$A$849,A144) -> 1 | AD18: 36.5 | AE18: 26.9
A19: NBF-17 | B19: NBF | C19: ＮＢＦ虎ノ門ビル（底地） | D19: オフィス | E19: 東京都 | F19: 港区 | G19: 港区芝3-2-18 | H19: 都心5区 | I19: 所有権（信託受益権） | J19: 1 | K19: 1895.59 | L19: 11661.69 | M19: 7253.87 | N19: 12 | O19: 2 | P19: 33086 | Q19: =IF(OR($A145="",P145=""),"",ROUND(YEARFRAC(P145,README!$C$5),1)) | R19: 46135 | S19: 11416 | T19: 11869.021 | U19: 18600 | V19: 6731 | Y19: 10.8 | Z19: NBF 2025年12月期(第49期)決算短信(2026/2/16公表) | AA19: 確認済 | AB19: オフィス。竣工年月・階数・面積は短信非掲載(有報等で補完予定)。2025/1/6付で建物を譲渡(売却益7,838千円)し底地のみ保有。NLA・稼働率・テナント数は開示対象外。取得価格は物件取得時の土地取得価格 | AC19: =COUNTIF(環境認証!$A$2:$A$849,A145) -> 1 | AD19: 56.7 | AE19: 62.9
A20: NBF-18 | B20: NBF | C20: グラントウキョウサウスタワー | D20: オフィス | E20: 東京都 | F20: 千代田区 | H20: 都心5区 | I20: 16物件（2026/3/31時点） | M20: 2175 | Q20: =IF(OR($A146="",P146=""),"",ROUND(YEARFRAC(P146,README!$C$5),1)) | S20: 9398.168 | T20: 9441.945 | U20: 9610 | V20: 168 | W20: 0.961 | X20: 4 | Y20: 1.9 | Z20: NBF 2025年12月期(第49期)決算短信(2026/2/16公表) | AA20: 確認済 | AB20: オフィス。竣工年月・階数・面積は短信非掲載(有報等で補完予定)。2021/1取得価格から2024/3一部譲渡持分(約80%)を控除した残存持分の価格 | AC20: =COUNTIF(環境認証!$A$2:$A$849,A146) -> 1 | AD20: 1.8 | AE20: 2.3
A21: NBF-19 | B21: NBF | C21: ＮＢＦ ＡＬＬＩＡＮＣＥ | D21: オフィス | E21: 東京都 | F21: 品川区 | H21: 都心5区 | M21: 4035 | Q21: =IF(OR($A147="",P147=""),"",ROUND(YEARFRAC(P147,README!$C$5),1)) | S21: 9126 | T21: 9562.539 | U21: 13700 | V21: 4137 | W21: 1 | X21: 5 | Y21: 4.5 | Z21: NBF 2025年12月期(第49期)決算短信(2026/2/16公表) | AA21: 確認済 | AB21: オフィス。竣工年月・階数・面積は短信非掲載(有報等で補完予定)。 | AC21: =COUNTIF(環境認証!$A$2:$A$849,A147) -> 2 | AD21: 43.3 | AE21: 50.1
A22: NBF-20 | B22: NBF | C22: 四谷メディカルビル | D22: オフィス | E22: 東京都 | F22: 新宿区 | H22: 都心5区 | M22: 7481 | Q22: =IF(OR($A148="",P148=""),"",ROUND(YEARFRAC(P148,README!$C$5),1)) | S22: 8800 | T22: 7512.403 | U22: 7460 | V22: -52 | W22: 0.971 | X22: 39 | Y22: 5.8 | Z22: NBF 2025年12月期(第49期)決算短信(2026/2/16公表) | AA22: 確認済 | AB22: オフィス。竣工年月・階数・面積は短信非掲載(有報等で補完予定)。鑑定評価額が取得価格を下回る数少ない物件。サブリース型(変動) | AC22: =COUNTIF(環境認証!$A$2:$A$849,A148) -> 1 | AD22: -0.7 | AE22: -15.2
A23: NBF-21 | B23: NBF | C23: ＮＢＦ渋谷イースト | D23: オフィス | E23: 東京都 | F23: 渋谷区 | H23: 都心5区 | M23: 4999 | Q23: =IF(OR($A149="",P149=""),"",ROUND(YEARFRAC(P149,README!$C$5),1)) | S23: 8000 | T23: 8279.706 | U23: 11000 | V23: 2720 | W23: 1 | X23: 4 | Y23: 7.9 | Z23: NBF 2025年12月期(第49期)決算短信(2026/2/16公表) | AA23: 確認済 | AB23: オフィス。竣工年月・階数・面積は短信非掲載(有報等で補完予定)。 | AC23: =COUNTIF(環境認証!$A$2:$A$849,A149) -> 1 | AD23: 32.9 | AE23: 37.5
A24: NBF-22 | B24: NBF | C24: ＮＢＦ高輪ビル | D24: オフィス | E24: 東京都 | F24: 港区 | H24: 都心5区 | M24: 10448 | Q24: =IF(OR($A150="",P150=""),"",ROUND(YEARFRAC(P150,README!$C$5),1)) | S24: 6667.2 | T24: 6027.755 | U24: 7850 | V24: 1822 | W24: 1 | X24: 13 | Y24: 1.8 | Z24: NBF 2025年12月期(第49期)決算短信(2026/2/16公表) | AA24: 確認済 | AB24: オフィス。竣工年月・階数・面積は短信非掲載(有報等で補完予定)。 | AC24: =COUNTIF(環境認証!$A$2:$A$849,A150) -> 1 | AD24: 30.2 | AE24: 17.7
A25: NBF-23 | B25: NBF | C25: ＮＢＦ赤坂山王スクエア | D25: オフィス | E25: 東京都 | F25: 港区 | H25: 都心5区 | M25: 5258 | Q25: =IF(OR($A151="",P151=""),"",ROUND(YEARFRAC(P151,README!$C$5),1)) | S25: 6250 | T25: 6277.029 | U25: 8140 | V25: 1863 | W25: 1 | X25: 6 | Y25: 6.3 | Z25: NBF 2025年12月期(第49期)決算短信(2026/2/16公表) | AA25: 確認済 | AB25: オフィス。竣工年月・階数・面積は短信非掲載(有報等で補完予定)。 | AC25: =COUNTIF(環境認証!$A$2:$A$849,A151) -> 1 | AD25: 29.7 | AE25: 30.2
A26: NBF-24 | B26: NBF | C26: ＮＢＦ神田須田町ビル | D26: オフィス | E26: 東京都 | F26: 千代田区 | H26: 都心5区 | M26: 4470 | Q26: =IF(OR($A152="",P152=""),"",ROUND(YEARFRAC(P152,README!$C$5),1)) | S26: 5960 | T26: 5086.939 | U26: 8680 | V26: 3593 | W26: 1 | X26: 10 | Y26: 0.2 | Z26: NBF 2025年12月期(第49期)決算短信(2026/2/16公表) | AA26: 確認済 | AB26: オフィス。竣工年月・階数・面積は短信非掲載(有報等で補完予定)。 | AC26: =COUNTIF(環境認証!$A$2:$A$849,A152) -> 0 | AD26: 70.6 | AE26: 45.6
A27: NBF-25 | B27: NBF | C27: ＮＢＦ小川町ビルディング | D27: オフィス | E27: 東京都 | F27: 千代田区 | H27: 都心5区 | M27: 5340 | Q27: =IF(OR($A153="",P153=""),"",ROUND(YEARFRAC(P153,README!$C$5),1)) | S27: 5420 | T27: 5400.299 | U27: 6600 | V27: 1200 | W27: 1 | X27: 18 | Y27: 4.7 | Z27: NBF 2025年12月期(第49期)決算短信(2026/2/16公表) | AA27: 確認済 | AB27: オフィス。竣工年月・階数・面積は短信非掲載(有報等で補完予定)。2005/9・2020/11の取得合計。サブリース型(変動) | AC27: =COUNTIF(環境認証!$A$2:$A$849,A153) -> 0 | AD27: 22.2 | AE27: 21.8
A28: NBF-26 | B28: NBF | C28: 住友電設ビル | D28: オフィス | E28: 東京都 | F28: 港区 | H28: 都心5区 | M28: 5971 | Q28: =IF(OR($A154="",P154=""),"",ROUND(YEARFRAC(P154,README!$C$5),1)) -> 16.7 | S28: 5365 | T28: 4796.836 | U28: 5360 | V28: 563 | W28: 1 | X28: 1 | Y28: 5.3 | Z28: NBF 2025年12月期(第49期)決算短信(2026/2/16公表) | AA28: 確認済 | AB28: オフィス。竣工年月・階数・面積は短信非掲載(有報等で補完予定)。2026/6/30付で三井不動産へ譲渡予定(譲渡価格10,000百万円=鑑定5,360百万円の約1.9倍、売却益5,112百万円見込)。港区三田・1991年6月竣工・SRC地下1階付12階建・延床9,185.13㎡(後発事象注記より) | AC28: =COUNTIF(環境認証!$A$2:$A$849,A154) -> 2 | AD28: 11.7 | AE28: -0.1
A29: NBF-27 | B29: NBF | C29: ＮＢＦ東銀座スクエア | D29: オフィス | E29: 東京都 | F29: 中央区 | G29: 港区赤坂1-8-1 | H29: 都心5区 | M29: 4871 | Q29: =IF(OR($A155="",P155=""),"",ROUND(YEARFRAC(P155,README!$C$5),1)) -> 23.3 | S29: 5200 | T29: 4232.236 | U29: 7990 | V29: 3758 | W29: 1 | X29: 8 | Y29: 1.9 | Z29: NBF 2025年12月期(第49期)決算短信(2026/2/16公表) | AA29: 確認済 | AB29: オフィス。竣工年月・階数・面積は短信非掲載(有報等で補完予定)。 | AC29: =COUNTIF(環境認証!$A$2:$A$849,A155) -> 1 | AD29: 88.8 | AE29: 53.7
A30: NBF-28 | B30: NBF | C30: 日本橋兜町Ｍ－ＳＱＵＡＲＥ | D30: オフィス | E30: 東京都 | F30: 中央区 | G30: 港区赤坂3-1-2 | H30: 都心5区 | M30: 3298 | Q30: =IF(OR($A156="",P156=""),"",ROUND(YEARFRAC(P156,README!$C$5),1)) -> 14 | S30: 4850 | T30: 4257.858 | U30: 5570 | V30: 1312 | W30: 1 | X30: 2 | Y30: 5.7 | Z30: NBF 2025年12月期(第49期)決算短信(2026/2/16公表) | AA30: 確認済 | AB30: オフィス。竣工年月・階数・面積は短信非掲載(有報等で補完予定)。 | AC30: =COUNTIF(環境認証!$A$2:$A$849,A156) -> 2 | AD30: 30.8 | AE30: 14.8
A31: NBF-29 | B31: NBF | C31: ＮＢＦ八丁堀テラス | D31: オフィス | E31: 東京都 | F31: 中央区 | H31: 都心5区 | M31: 5270 | Q31: =IF(OR($A157="",P157=""),"",ROUND(YEARFRAC(P157,README!$C$5),1)) -> 16.6 | S31: 4528.349 | T31: 4101.664 | U31: 5540 | V31: 1438 | W31: 1 | X31: 1 | Y31: 7 | Z31: NBF 2025年12月期(第49期)決算短信(2026/2/16公表) | AA31: 確認済 | AB31: オフィス。竣工年月・階数・面積は短信非掲載(有報等で補完予定)。旧NBF新川ビルの取得価格を2020/6/30鑑定評価額比率で按分した金額 | AC31: =COUNTIF(環境認証!$A$2:$A$849,A157) -> 1 | AD31: 35.1 | AE31: 22.3
A32: NBF-30 | B32: NBF | C32: 龍角散ビル | D32: オフィス | E32: 東京都 | F32: 千代田区 | H32: 都心5区 | M32: 5332 | Q32: =IF(OR($A158="",P158=""),"",ROUND(YEARFRAC(P158,README!$C$5),1)) -> 16 | S32: 4050 | T32: 4327.607 | U32: 5270 | V32: 942 | W32: 1 | X32: 16 | Y32: 5.4 | Z32: NBF 2025年12月期(第49期)決算短信(2026/2/16公表) | AA32: 確認済 | AB32: オフィス。竣工年月・階数・面積は短信非掲載(有報等で補完予定)。 | AC32: =COUNTIF(環境認証!$A$2:$A$849,A158) -> 2 | AD32: 21.8 | AE32: 30.1
A33: NBF-31 | B33: NBF | C33: 神宮前Ｍ－ＳＱＵＡＲＥ | D33: オフィス | E33: 東京都 | F33: 渋谷区 | H33: 都心5区 | M33: 7213 | Q33: =IF(OR($A159="",P159=""),"",ROUND(YEARFRAC(P159,README!$C$5),1)) -> 16.5 | S33: 3700 | T33: 2596.703 | U33: 4320 | V33: 1723 | W33: 0.88 | X33: 7 | Y33: 5 | Z33: NBF 2025年12月期(第49期)決算短信(2026/2/16公表) | AA33: 確認済 | AB33: オフィス。竣工年月・階数・面積は短信非掲載(有報等で補完予定)。 | AC33: =COUNTIF(環境認証!$A$2:$A$849,A159) -> 1 | AD33: 66.4 | AE33: 16.8
A34: NBF-32 | B34: NBF | C34: 豊洲ベイサイドクロスタワー | D34: オフィス | E34: 東京都 | F34: 江東区 | H34: その他東京23区 | M34: 51512 | Q34: =IF(OR($A160="",P160=""),"",ROUND(YEARFRAC(P160,README!$C$5),1)) -> 24.4 | S34: 80100 | T34: 78755.379 | U34: 80900 | V34: 2145 | W34: 1 | X34: 4 | Y34: 1.7 | Z34: NBF 2025年12月期(第49期)決算短信(2026/2/16公表) | AA34: 確認済 | AB34: オフィス。竣工年月・階数・面積は短信非掲載(有報等で補完予定)。区分所有権(2022〜2024年3回取得・既存保有約47.69%)。2026/3/31付で追加取得予定(約9.19%・14,810百万円→合計約56.88%)。2020年3月竣工・地下2階付36階建・延床178,504.10㎡(建物全体)。店舗区画は固定賃料型ML | AC34: =COUNTIF(環境認証!$A$2:$A$849,A160) -> 1 | AD34: 2.7 | AE34: 1
A35: NBF-33 | B35: NBF | C35: ＮＢＦ大崎ビル | D35: オフィス | E35: 東京都 | F35: 品川区 | H35: その他東京23区 | M35: 74425 | Q35: =IF(OR($A161="",P161=""),"",ROUND(YEARFRAC(P161,README!$C$5),1)) -> 3.6 | S35: 66660 | T35: 59991.582 | U35: 87400 | V35: 27408 | W35: 1 | X35: 3 | Y35: 1.8 | Z35: NBF 2025年12月期(第49期)決算短信(2026/2/16公表) | AA35: 確認済 | AB35: オフィス。竣工年月・階数・面積は短信非掲載(有報等で補完予定)。主要テナント:ソニーグループ(賃貸面積73,477㎡=ポートフォリオ全体の6.0%) | AC35: =COUNTIF(環境認証!$A$2:$A$849,A161) -> 1 | AD35: 45.7 | AE35: 31.1
A36: NBF-34 | B36: NBF | C36: ゲートシティ大崎 | D36: オフィス | E36: 東京都 | F36: 品川区 | H36: その他東京23区 | M36: 41880 | Q36: =IF(OR($A162="",P162=""),"",ROUND(YEARFRAC(P162,README!$C$5),1)) -> 31.4 | S36: 57281.06 | T36: 47525.115 | U36: 72000 | V36: 24475 | W36: 0.996 | X36: 80 | Y36: 4 | Z36: NBF 2025年12月期(第49期)決算短信(2026/2/16公表) | AA36: 確認済 | AB36: オフィス。竣工年月・階数・面積は短信非掲載(有報等で補完予定)。2006・2011・2013年の3回取得合計。サブリース型(変動) | AC36: =COUNTIF(環境認証!$A$2:$A$849,A162) -> 1 | AD36: 51.5 | AE36: 25.7
A37: NBF-35 | B37: NBF | C37: ＮＢＦ豊洲キャナルフロント | D37: オフィス | E37: 東京都 | F37: 江東区 | H37: その他東京23区 | M37: 36639 | Q37: =IF(OR($A163="",P163=""),"",ROUND(YEARFRAC(P163,README!$C$5),1)) -> 17.1 | S37: 35200 | T37: 27034.033 | U37: 38500 | V37: 11466 | W37: 1 | X37: 17 | Y37: 3.2 | Z37: NBF 2025年12月期(第49期)決算短信(2026/2/16公表) | AA37: 確認済 | AB37: オフィス。竣工年月・階数・面積は短信非掲載(有報等で補完予定)。主要テナント:ソフトバンク | AC37: =COUNTIF(環境認証!$A$2:$A$849,A163) -> 0 | AD37: 42.4 | AE37: 9.4
A38: NBF-36 | B38: NBF | C38: 上野イーストタワー | D38: オフィス | E38: 東京都 | F38: 台東区 | H38: その他東京23区 | M38: 28711 | Q38: =IF(OR($A164="",P164=""),"",ROUND(YEARFRAC(P164,README!$C$5),1)) -> 35.8 | S38: 35000 | T38: 32031.252 | U38: 42300 | V38: 10269 | W38: 1 | X38: 2 | Y38: 3.2 | Z38: NBF 2025年12月期(第49期)決算短信(2026/2/16公表) | AA38: 確認済 | AB38: オフィス。竣工年月・階数・面積は短信非掲載(有報等で補完予定)。2016/6・2021/3の取得合計。主要テナント:日立リアルエステートパートナーズ | AC38: =COUNTIF(環境認証!$A$2:$A$849,A164) -> 1 | AD38: 32.1 | AE38: 20.9
A39: NBF-37 | B39: NBF | C39: ＮＢＦ豊洲ガーデンフロント | D39: オフィス | E39: 東京都 | F39: 江東区 | H39: その他東京23区 | M39: 28299 | Q39: =IF(OR($A165="",P165=""),"",ROUND(YEARFRAC(P165,README!$C$5),1)) -> 11.4 | S39: 25018 | T39: 21221.922 | U39: 30100 | V39: 8878 | W39: 1 | X39: 5 | Y39: 4.2 | Z39: NBF 2025年12月期(第49期)決算短信(2026/2/16公表) | AA39: 確認済 | AB39: オフィス。竣工年月・階数・面積は短信非掲載(有報等で補完予定)。主要テナント:博報堂DYホールディングス | AC39: =COUNTIF(環境認証!$A$2:$A$849,A165) -> 0 | AD39: 41.8 | AE39: 20.3
A40: NBF-38 | B40: NBF | C40: 大崎ブライトコア・ブライトプラザ | D40: オフィス | E40: 東京都 | F40: 品川区 | H40: その他東京23区 | M40: 14179 | Q40: =IF(OR($A166="",P166=""),"",ROUND(YEARFRAC(P166,README!$C$5),1)) -> 26.2 | S40: 24380 | T40: 22582.726 | U40: 25600 | V40: 3017 | W40: 0.994 | X40: 22 | Y40: 5.5 | Z40: NBF 2025年12月期(第49期)決算短信(2026/2/16公表) | AA40: 確認済 | AB40: オフィス。竣工年月・階数・面積は短信非掲載(有報等で補完予定)。2016〜2020年の5回分割取得合計。サブリース型(変動) | AC40: =COUNTIF(環境認証!$A$2:$A$849,A166) -> 1 | AD40: 13.4 | AE40: 5
...

Sheet 物件収支
A1: 物件ID | B1: 法人ID | C1: 決算期 | D1: 期間月数 | E1: 開示区分 | F1: 賃貸事業収入合計(千円) | G1: うち賃料・共益費(千円) | H1: うちその他収入(千円) | I1: 賃貸事業費用合計(千円) | J1: うち外注委託費(千円) | K1: うち水道光熱費(千円) | L1: うち公租公課(千円) | M1: うち損害保険料(千円) | N1: うち修繕費(千円) | O1: うち減価償却費(千円) | P1: うちその他費用(千円) | Q1: 賃貸事業損益(千円) | R1: NOI(千円) | S1: 資本的支出(千円) | T1: NCF(千円) | U1: 内訳チェック(0=整合) | V1: 出典（資料名・頁） | W1: 確認ステータス | X1: 備考 | Y1: 通期保有フラグ | Z1: 年換算の妥当性 | AA1: 収入の単位精度
A2: NBF-ALL | B2: NBF | C2: 2025年12月期（第49期） | D2: 6 | E2: 開示（法人一括） | F2: 48547009 | G2: 44809206 | H2: 3737803 | I2: 25250123 | J2: 7600503 | K2: 0 | L2: 4854835 | M2: 43257 | N2: 976251 | O2: 7852749 | P2: 3922526 | Q2: =IF($A198="","",IF(OR(F198="",I198=""),"",F198-I198)) -> -24977805 | R2: =IF($A198="","",IF(Q198="","",Q198+IF(O198="",0,O198))) -> 8394749 | S2: 4987000 | T2: =IF($A198="","",IF(R198="","",R198-IF(S198="",0,S198))) -> -5234000 | U2: =IF($A198="","",IF(I198="","",I198-SUM(J198:P198))) -> 2 | V2: NBF 2025年12月期(第49期)決算短信(2026/2/16公表) p.20 不動産等賃貸事業損益の内訳・p.36-37 資本的支出 | W2: 確認済※ | X2: 法人一括収支(千円)。G=不動産賃貸収入(家賃42,402,552+共益費2,022,901+その他賃貸収入383,752)、H=その他賃貸事業収入(駐車場697,134/施設使用料311,730/付帯収益2,604,635/解約金58,998/雑収益65,304)。J=外注委託費。K水道光熱費は独立科目なし(その他費用「諸経費」3,922,526に含む)→K=0は科目非区分のため費用構造比較で留意。内訳チェック2千円は原資料の千円未満切捨て由来。損益23,296,886(開示一致)。CAPEX4,987百万円+費用処理修繕976百万円=5,964百万円の工事実施。当期不動産売却なし(前期は芝NBFタワー等で売却益4,847百万円)。開示59物件の収益計39,685百万円+非開示11物件残差8,862百万円(一括比18.3%)=一括48,547百万円と整合(非開示11物件の取得価格比率19.2%と符合) | Y2: ○（通期保有） | Z2: 年換算可 | AA2: 千円単位（正確値）
A3: NBF-01 | B3: NBF | C3: 2025年12月期（第49期） | D3: 6 | E3: 開示（物件別・収益のみ、百万円単位） | F3: 5077000 | Q3: =IF($A128="","",IF(OR(F128="",I128=""),"",F128-I128)) -> 242000 | R3: =IF($A128="","",IF(Q128="","",Q128+IF(O128="",0,O128))) -> 283000 | T3: =IF($A128="","",IF(R128="","",R128-IF(S128="",0,S128))) | U3: =IF($A128="","",IF(I128="","",I128-SUM(J128:P128))) -> 2000 | V3: NBF 2025年12月期(第49期)決算短信(2026/2/16公表) p.31-32 テナント等の概要 | W3: 確認済 | X3: 総賃貸収入(=当該物件の営業収益計・百万円未満切捨て)を千円換算した概数。費用内訳は物件別非開示(法人一括のNBF-ALL行参照)。J-REIT運用資産中最大の旗艦物件。サブリース型(変動賃料) | Y3: ○（通期保有） | Z3: 年換算可 | AA3: 百万円単位（下3桁は概数）
A4: NBF-02 | B4: NBF | C4: 2025年12月期（第49期） | D4: 6 | E4: 開示（物件別・収益のみ、百万円単位） | F4: 3084000 | Q4: =IF($A129="","",IF(OR(F129="",I129=""),"",F129-I129)) -> 98000 | R4: =IF($A129="","",IF(Q129="","",Q129+IF(O129="",0,O129))) -> 243000 | T4: =IF($A129="","",IF(R129="","",R129-IF(S129="",0,S129))) | U4: =IF($A129="","",IF(I129="","",I129-SUM(J129:P129))) -> 2000 | V4: NBF 2025年12月期(第49期)決算短信(2026/2/16公表) p.31-32 テナント等の概要 | W4: 確認済 | X4: 総賃貸収入(=当該物件の営業収益計・百万円未満切捨て)を千円換算した概数。費用内訳は物件別非開示(法人一括のNBF-ALL行参照)。2021/9・2022/3・2023/3の3回取得合計。サブリース型(変動) | Y4: ○（通期保有） | Z4: 年換算可 | AA4: 百万円単位（下3桁は概数）
A5: NBF-03 | B5: NBF | C5: 2025年12月期（第49期） | D5: 6 | E5: 開示（物件別・収益のみ、百万円単位） | F5: 1532000 | Q5: =IF($A130="","",IF(OR(F130="",I130=""),"",F130-I130)) -> 19000 | R5: =IF($A130="","",IF(Q130="","",Q130+IF(O130="",0,O130))) -> 32000 | T5: =IF($A130="","",IF(R130="","",R130-IF(S130="",0,S130))) | U5: =IF($A130="","",IF(I130="","",I130-SUM(J130:P130))) -> 1000 | V5: NBF 2025年12月期(第49期)決算短信(2026/2/16公表) p.31-32 テナント等の概要 | W5: 確認済 | X5: 総賃貸収入(=当該物件の営業収益計・百万円未満切捨て)を千円換算した概数。費用内訳は物件別非開示(法人一括のNBF-ALL行参照)。サブリース型(変動) | Y5: ○（通期保有） | Z5: 年換算可 | AA5: 百万円単位（下3桁は概数）
A6: NBF-04 | B6: NBF | C6: 2025年12月期（第49期） | D6: 6 | E6: 開示（物件別・収益のみ、百万円単位） | F6: 1283000 | Q6: =IF($A131="","",IF(OR(F131="",I131=""),"",F131-I131)) -> 386000 | R6: =IF($A131="","",IF(Q131="","",Q131+IF(O131="",0,O131))) -> 453000 | T6: =IF($A131="","",IF(R131="","",R131-IF(S131="",0,S131))) | U6: =IF($A131="","",IF(I131="","",I131-SUM(J131:P131))) -> 2000 | V6: NBF 2025年12月期(第49期)決算短信(2026/2/16公表) p.31-32 テナント等の概要 | W6: 確認済 | X6: 総賃貸収入(=当該物件の営業収益計・百万円未満切捨て)を千円換算した概数。費用内訳は物件別非開示(法人一括のNBF-ALL行参照)。任意組合出資持分(西新宿六丁目共有組合)含む。2002〜2023年の8回分割取得合計。サブリース型(変動) | Y6: ○（通期保有） | Z6: 年換算可 | AA6: 百万円単位（下3桁は概数）
A7: NBF-05 | B7: NBF | C7: 2025年12月期（第49期） | D7: 6 | E7: 開示（物件別・収益のみ、百万円単位） | F7: 1481000 | Q7: =IF($A132="","",IF(OR(F132="",I132=""),"",F132-I132)) -> 17000 | R7: =IF($A132="","",IF(Q132="","",Q132+IF(O132="",0,O132))) -> 40000 | T7: =IF($A132="","",IF(R132="","",R132-IF(S132="",0,S132))) | U7: =IF($A132="","",IF(I132="","",I132-SUM(J132:P132))) -> 3000 | V7: NBF 2025年12月期(第49期)決算短信(2026/2/16公表) p.31-32 テナント等の概要 | W7: 確認済 | X7: 総賃貸収入(=当該物件の営業収益計・百万円未満切捨て)を千円換算した概数。費用内訳は物件別非開示(法人一括のNBF-ALL行参照)。2013/5・2018/3の取得合計。ホテル部分は固定賃料契約 | Y7: ○（通期保有） | Z7: 年換算可 | AA7: 百万円単位（下3桁は概数）
A8: NBF-06 | B8: NBF | C8: 2025年12月期（第49期） | D8: 6 | E8: 非開示（テナント同意なし） | F8: 1001000 | Q8: =IF($A133="","",IF(OR(F133="",I133=""),"",F133-I133)) -> 352000 | R8: =IF($A133="","",IF(Q133="","",Q133+IF(O133="",0,O133))) -> 486000 | T8: =IF($A133="","",IF(R133="","",R133-IF(S133="",0,S133))) | U8: =IF($A133="","",IF(I133="","",I133-SUM(J133:P133))) -> 3000 | V8: NBF 2025年12月期(第49期)決算短信(2026/2/16公表) p.31-32 | W8: 確認済 | X8: テナント又は共有者の同意が得られず収益非開示(短信注3)。主要テナント:楽天グループ | Y8: ○（通期保有） | Z8: 年換算可 | AA8: 千円単位（正確値）
A9: NBF-07 | B9: NBF | C9: 2025年12月期（第49期） | D9: 6 | E9: 開示（物件別・収益のみ、百万円単位） | F9: 1420000 | Q9: =IF($A134="","",IF(OR(F134="",I134=""),"",F134-I134)) -> 9000 | R9: =IF($A134="","",IF(Q134="","",Q134+IF(O134="",0,O134))) -> 39000 | T9: =IF($A134="","",IF(R134="","",R134-IF(S134="",0,S134))) | U9: =IF($A134="","",IF(I134="","",I134-SUM(J134:P134))) -> 2000 | V9: NBF 2025年12月期(第49期)決算短信(2026/2/16公表) p.31-32 テナント等の概要 | W9: 確認済 | X9: 総賃貸収入(=当該物件の営業収益計・百万円未満切捨て)を千円換算した概数。費用内訳は物件別非開示(法人一括のNBF-ALL行参照)。鑑定評価額60,800百万円は取得価格の約2倍。主要テナント:アクサ生命 | Y9: ○（通期保有） | Z9: 年換算可 | AA9: 百万円単位（下3桁は概数）
A10: NBF-08 | B10: NBF | C10: 2025年12月期（第49期） | D10: 6 | E10: 開示（物件別・収益のみ、百万円単位） | F10: 856000 | Q10: =IF($A135="","",IF(OR(F135="",I135=""),"",F135-I135)) -> 217000 | R10: =IF($A135="","",IF(Q135="","",Q135+IF(O135="",0,O135))) -> 321000 | T10: =IF($A135="","",IF(R135="","",R135-IF(S135="",0,S135))) | U10: =IF($A135="","",IF(I135="","",I135-SUM(J135:P135))) -> 3000 | V10: NBF 2025年12月期(第49期)決算短信(2026/2/16公表) p.31-32 テナント等の概要 | W10: 確認済 | X10: 総賃貸収入(=当該物件の営業収益計・百万円未満切捨て)を千円換算した概数。費用内訳は物件別非開示(法人一括のNBF-ALL行参照) | Y10: ○（通期保有） | Z10: 年換算可 | AA10: 百万円単位（下3桁は概数）
A11: NBF-09 | B11: NBF | C11: 2025年12月期（第49期） | D11: 6 | E11: 開示（物件別・収益のみ、百万円単位） | F11: 551000 | Q11: =IF($A136="","",IF(OR(F136="",I136=""),"",F136-I136)) -> 54000 | R11: =IF($A136="","",IF(Q136="","",Q136+IF(O136="",0,O136))) -> 81000 | T11: =IF($A136="","",IF(R136="","",R136-IF(S136="",0,S136))) | U11: =IF($A136="","",IF(I136="","",I136-SUM(J136:P136))) -> 3000 | V11: NBF 2025年12月期(第49期)決算短信(2026/2/16公表) p.31-32 テナント等の概要 | W11: 確認済 | X11: 総賃貸収入(=当該物件の営業収益計・百万円未満切捨て)を千円換算した概数。費用内訳は物件別非開示(法人一括のNBF-ALL行参照)。2019年3・4月の取得合計 | Y11: ○（通期保有） | Z11: 年換算可 | AA11: 百万円単位（下3桁は概数）
A12: NBF-10 | B12: NBF | C12: 2025年12月期（第49期） | D12: 6 | E12: 開示（物件別・収益のみ、百万円単位） | F12: 889000 | Q12: =IF($A137="","",IF(OR(F137="",I137=""),"",F137-I137)) -> 99000 | R12: =IF($A137="","",IF(Q137="","",Q137+IF(O137="",0,O137))) -> 163000 | T12: =IF($A137="","",IF(R137="","",R137-IF(S137="",0,S137))) | U12: =IF($A137="","",IF(I137="","",I137-SUM(J137:P137))) -> 3000 | V12: NBF 2025年12月期(第49期)決算短信(2026/2/16公表) p.31-32 テナント等の概要 | W12: 確認済 | X12: 総賃貸収入(=当該物件の営業収益計・百万円未満切捨て)を千円換算した概数。費用内訳は物件別非開示(法人一括のNBF-ALL行参照)。敷地の賃借権を含む。2004/11・2006/4の取得合計。サブリース型(変動) | Y12: ○（通期保有） | Z12: 年換算可 | AA12: 百万円単位（下3桁は概数）
A13: NBF-11 | B13: NBF | C13: 2025年12月期（第49期） | D13: 6 | E13: 非開示（テナント同意なし） | F13: 91000 | Q13: =IF($A138="","",IF(OR(F138="",I138=""),"",F138-I138)) -> 202000 | R13: =IF($A138="","",IF(Q138="","",Q138+IF(O138="",0,O138))) -> 265000 | T13: =IF($A138="","",IF(R138="","",R138-IF(S138="",0,S138))) | U13: =IF($A138="","",IF(I138="","",I138-SUM(J138:P138))) -> 3000 | V13: NBF 2025年12月期(第49期)決算短信(2026/2/16公表) p.31-32 | W13: 確認済 | X13: テナント又は共有者の同意が得られず収益非開示(短信注3)。2004/2・2013/3の取得合計。主要テナント:インフィニオンテクノロジーズジャパン | Y13: ○（通期保有） | Z13: 年換算可 | AA13: 千円単位（正確値）
A14: NBF-12 | B14: NBF | C14: 2025年12月期（第49期） | D14: 6 | E14: 非開示（テナント同意なし） | F14: 274000 | Q14: =IF($A139="","",IF(OR(F139="",I139=""),"",F139-I139)) -> 58000 | R14: =IF($A139="","",IF(Q139="","",Q139+IF(O139="",0,O139))) -> 205000 | T14: =IF($A139="","",IF(R139="","",R139-IF(S139="",0,S139))) | U14: =IF($A139="","",IF(I139="","",I139-SUM(J139:P139))) -> 4000 | V14: NBF 2025年12月期(第49期)決算短信(2026/2/16公表) p.31-32 | W14: 確認済 | X14: テナント又は共有者の同意が得られず収益非開示(短信注3)。地上権を含む | Y14: ○（通期保有） | Z14: 年換算可 | AA14: 千円単位（正確値）
... A18: NBF-16 | B18: NBF | C18: 2025年12月期（第49期） | D18: 6 | E18: 開示（物件別・収益のみ、百万円単位） | F18: 318000 | Q18: =IF($A143="","",IF(OR(F143="",I143=""),"",F143-I143)) -> 259000 | R18: =IF($A143="","",IF(Q143="","",Q143+IF(O143="",0,O143))) -> 349000 | T18: =IF($A143="","",IF(R143="","",R143-IF(S143="",0,S143))) | U18: =IF($A143="","",IF(I143="","",I143-SUM(J143:P143))) -> 2000 | V18: NBF 2025年12月期(第49期)決算短信(2026/2/16公表) p.31-32 テナント等の概要 | W18: 確認済 | X18: 総賃貸収入(=当該物件の営業収益計・百万円未満切捨て)を千円換算した概数。費用内訳は物件別非開示(法人一括のNBF-ALL行参照) | Y18: ○（通期保有） | Z18: 年換算可 | AA18: 百万円単位（下3桁は概数）
A19: NBF-17 | B19: NBF | C19: 2025年12月期（第49期） | D19: 6 | E19: 開示（物件別・収益のみ、百万円単位） | F19: 98000 | G19: 5013812 | H19: 525450 | I19: 2268046 | J19: 569792 | K19: 362982 | L19: 429193 | M19: 12561 | N19: 102215 | O19: 774962 | P19: 16338 | Q19: =IF($A144="","",IF(OR(F144="",I144=""),"",F144-I144)) -> 146000 | R19: =IF($A144="","",IF(Q144="","",Q144+IF(O144="",0,O144))) -> 170000 | S19: 624656 | T19: =IF($A144="","",IF(R144="","",R144-IF(S144="",0,S144))) | U19: =IF($A144="","",IF(I144="","",I144-SUM(J144:P144))) -> 3000 | V19: NBF 2025年12月期(第49期)決算短信(2026/2/16公表) p.31-32 テナント等の概要 | W19: 確認済 | X19: 総賃貸収入(=当該物件の営業収益計・百万円未満切捨て)を千円換算した概数。費用内訳は物件別非開示(法人一括のNBF-ALL行参照)。2025/1/6付で建物を譲渡(売却益7,838千円)し底地のみ保有。NL稼働率・テナント数は開示対象外。取得価格は物件取得時の土地取得価格 | Y19: ○（通期保有） | Z19: 年換算可 | AA19: 百万円単位（下3桁は概数）
A20: NBF-18 | B20: NBF | C20: 2025年12月期（第49期） | D20: 6 | E20: 開示（物件別・収益のみ、百万円単位） | F20: 151000 | Q20: =IF($A145="","",IF(OR(F145="",I145=""),"",F145-I145)) -> 168000 | R20: =IF($A145="","",IF(Q145="","",Q145+IF(O145="",0,O145))) -> 298000 | T20: =IF($A145="","",IF(R145="","",R145-IF(S145="",0,S145))) | U20: =IF($A145="","",IF(I145="","",I145-SUM(J145:P145))) -> 3000 | V20: NBF 2025年12月期(第49期)決算短信(2026/2/16公表) p.31-32 テナント等の概要 | W20: 確認済 | X20: 総賃貸収入(=当該物件の営業収益計・百万円未満切捨て)を千円換算した概数。費用内訳は物件別非開示(法人一括のNBF-ALL行参照)。2021/1取得価格から2024/3一部譲渡持分(約80%)を控除した残存持分の価格 | Y20: ×（期の一部のみ） | Z20: 年換算値は実態と乖離するため利回り算定に用いない（期中の持分譲渡により分母（取得価格）のみ減額） | AA20: 百万円単位（下3桁は概数）
A21: NBF-19 | B21: NBF | C21: 2025年12月期（第49期） | D21: 6 | E21: 開示（物件別・収益のみ、百万円単位） | F21: 323000 | Q21: =IF($A146="","",IF(OR(F146="",I146=""),"",F146-I146)) -> 294000 | R21: =IF($A146="","",IF(Q146="","",Q146+IF(O146="",0,O146))) -> 377000 | T21: =IF($A146="","",IF(R146="","",R146-IF(S146="",0,S146))) | U21: =IF($A146="","",IF(I146="","",I146-SUM(J146:P146))) -> 3000 | V21: NBF 2025年12月期(第49期)決算短信(2026/2/16公表) p.31-32 テナント等の概要 | W21: 確認済 | X21: 総賃貸収入(=当該物件の営業収益計・百万円未満切捨て)を千円換算した概数。費用内訳は物件別非開示(法人一括のNBF-ALL行参照) | Y21: ○（通期保有） | Z21: 年換算可 | AA21: 百万円単位（下3桁は概数）
A22: NBF-20 | B22: NBF | C22: 2025年12月期（第49期） | D22: 6 | E22: 開示（物件別・収益のみ、百万円単位） | F22: 236000 | Q22: =IF($A147="","",IF(OR(F147="",I147=""),"",F147-I147)) -> 235000 | R22: =IF($A147="","",IF(Q147="","",Q147+IF(O147="",0,O147))) -> 309000 | T22: =IF($A147="","",IF(R147="","",R147-IF(S147="",0,S147))) | U22: =IF($A147="","",IF(I147="","",I147-SUM(J147:P147))) -> 3000 | V22: NBF 2025年12月期(第49期)決算短信(2026/2/16公表) p.31-32 テナント等の概要 | W22: 確認済 | X22: 総賃貸収入(=当該物件の営業収益計・百万円未満切捨て)を千円換算した概数。費用内訳は物件別非開示(法人一括のNBF-ALL行参照)。鑑定評価額が取得価格を下回る数少ない物件。サブリース型(変動) | Y22: ○（通期保有） | Z22: 年換算可 | AA22: 百万円単位（下3桁は概数）
A23: NBF-21 | B23: NBF | C23: 2025年12月期（第49期） | D23: 6 | E23: 開示（物件別・収益のみ、百万円単位） | F23: 242000 | Q23: =IF($A148="","",IF(OR(F148="",I148=""),"",F148-I148)) -> 83000 | R23: =IF($A148="","",IF(Q148="","",Q148+IF(O148="",0,O148))) -> 127000 | T23: =IF($A148="","",IF(R148="","",R148-IF(S148="",0,S148))) | U23: =IF($A148="","",IF(I148="","",I148-SUM(J148:P148))) -> 1000 | V23: NBF 2025年12月期(第49期)決算短信(2026/2/16公表) p.31-32 テナント等の概要 | W23: 確認済 | X23: 総賃貸収入(=当該物件の営業収益計・百万円未満切捨て)を千円換算した概数。費用内訳は物件別非開示(法人一括のNBF-ALL行参照) | Y23: ○（通期保有） | Z23: 年換算可 | AA23: 百万円単位（下3桁は概数）
A24: NBF-22 | B24: NBF | C24: 2025年12月期（第49期） | D24: 6 | E24: 開示（物件別・収益のみ、百万円単位） | F24: 304000 | Q24: =IF($A149="","",IF(OR(F149="",I149=""),"",F149-I149)) -> 24000 | R24: =IF($A149="","",IF(Q149="","",Q149+IF(O149="",0,O149))) -> 107000 | T24: =IF($A149="","",IF(R149="","",R149-IF(S149="",0,S149))) | U24: =IF($A149="","",IF(I149="","",I149-SUM(J149:P149))) -> 3000 | V24: NBF 2025年12月期(第49期)決算短信(2026/2/16公表) p.31-32 テナント等の概要 | W24: 確認済 | X24: 総賃貸収入(=当該物件の営業収益計・百万円未満切捨て)を千円換算した概数。費用内訳は物件別非開示(法人一括のNBF-ALL行参照) | Y24: ○（通期保有） | Z24: 年換算可 | AA24: 百万円単位（下3桁は概数）
A25: NBF-23 | B25: NBF | C25: 2025年12月期（第49期） | D25: 6 | E25: 開示（物件別・収益のみ、百万円単位） | F25: 203000 | Q25: =IF($A150="","",IF(OR(F150="",I150=""),"",F150-I150)) -> 50000 | R25: =IF($A150="","",IF(Q150="","",Q150+IF(O150="",0,O150))) -> 64000 | T25: =IF($A150="","",IF(R150="","",R150-IF(S150="",0,S150))) | U25: =IF($A150="","",IF(I150="","",I150-SUM(J150:P150))) -> 1000 | V25: NBF 2025年12月期(第49期)決算短信(2026/2/16公表) p.31-32 テナント等の概要 | W25: 確認済 | X25: 総賃貸収入(=当該物件の営業収益計・百万円未満切捨て)を千円換算した概数。費用内訳は物件別非開示(法人一括のNBF-ALL行参照) | Y25: ○（通期保有） | Z25: 年換算可 | AA25: 百万円単位（下3桁は概数）
A26: NBF-24 | B26: NBF | C26: 2025年12月期（第49期） | D26: 6 | E26: 開示（物件別・収益のみ、百万円単位） | F26: 211000 | Q26: =IF($A151="","",IF(OR(F151="",I151=""),"",F151-I151)) -> 20000 | R26: =IF($A151="","",IF(Q151="","",Q151+IF(O151="",0,O151))) -> 88000 | T26: =IF($A151="","",IF(R151="","",R151-IF(S151="",0,S151))) | U26: =IF($A151="","",IF(I151="","",I151-SUM(J151:P151))) -> 1000 | V26: NBF 2025年12月期(第49期)決算短信(2026/2/16公表) p.31-32 テナント等の概要 | W26: 確認済 | X26: 総賃貸収入(=当該物件の営業収益計・百万円未満切捨て)を千円換算した概数。費用内訳は物件別非開示(法人一括のNBF-ALL行参照) | Y26: ○（通期保有） | Z26: 年換算可 | AA26: 百万円単位（下3桁は概数）
A27: NBF-25 | B27: NBF | C27: 2025年12月期（第49期） | D27: 6 | E27: 開示（物件別・収益のみ、百万円単位） | F27: 199000 | Q27: =IF($A152="","",IF(OR(F152="",I152=""),"",F152-I152)) -> 79000 | R27: =IF($A152="","",IF(Q152="","",Q152+IF(O152="",0,O152))) -> 97000 | T27: =IF($A152="","",IF(R152="","",R152-IF(S152="",0,S152))) | U27: =IF($A152="","",IF(I152="","",I152-SUM(J152:P152))) -> 2000 | V27: NBF 2025年12月期(第49期)決算短信(2026/2/16公表) p.31-32 テナント等の概要 | W27: 確認済 | X27: 総賃貸収入(=当該物件の営業収益計・百万円未満切捨て)を千円換算した概数。費用内訳は物件別非開示(法人一括のNBF-ALL行参照)。2005/9・2020/11の取得合計。サブリース型(変動) | Y27: ○（通期保有） | Z27: 年換算可 | AA27: 百万円単位（下3桁は概数）
A28: NBF-26 | B28: NBF | C28: 2025年12月期（第49期） | D28: 6 | E28: 非開示（テナント同意なし） | Q28: =IF($A153="","",IF(OR(F153="",I153=""),"",F153-I153)) -> 3271216 | R28: =IF($A153="","",IF(Q153="","",Q153+IF(O153="",0,O153))) -> -1395084 | T28: =IF($A153="","",IF(R153="","",R153-IF(S153="",0,S153))) -> 296306 | U28: =IF($A153="","",IF(I153="","",I153-SUM(J153:P153))) -> 3 | V28: NBF 2025年12月期(第49期)決算短信(2026/2/16公表) p.31-32 | W28: 確認済 | X28: テナント又は共有者の同意が得られず収益非開示(短信注3)。2026/6/30付で三井不動産へ譲渡予定(譲渡価格10,000百万円=鑑定5,360百万円の約1.9倍、売却益5,112百万円見込)。港区三田・1991年6月竣工・SRC地下1階付12階建・延床9,185.13㎡(後発事象注記より) | Y28: ○（通期保有） | Z28: 年換算可 | AA28: 千円単位（正確値）
A29: NBF-27 | B29: NBF | C29: 2025年12月期（第49期） | D29: 6 | E29: 開示（物件別・収益のみ、百万円単位） | F29: 194000 | Q29: =IF($A154="","",IF(OR(F154="",I154=""),"",F154-I154)) | R29: =IF($A154="","",IF(Q154="","",Q154+IF(O154="",0,O154))) -> 23296886 | T29: =IF($A154="","",IF(R154="","",R154-IF(S154="",0,S154))) -> -17125056 | U29: =IF($A154="","",IF(I154="","",I154-SUM(J154:P154))) | V29: NBF 2025年12月期(第49期)決算短信(2026/2/16公表) p.31-32 テナント等の概要 | W29: 確認済 | X29: 総賃貸収入(=当該物件の営業収益計・百万円未満切捨て)を千円換算した概数。費用内訳は物件別非開示(法人一括のNBF-ALL行参照) | Y29: ○（通期保有） | Z29: 年換算可 | AA29: 百万円単位（下3桁は概数）
A30: NBF-28 | B30: NBF | C30: 2025年12月期（第49期） | D30: 6 | E30: 非開示（テナント同意なし） | Q30: =IF($A155="","",IF(OR(F155="",I155=""),"",F155-I155)) | R30: =IF($A155="","",IF(Q155="","",Q155+IF(O155="",0,O155))) | T30: =IF($A155="","",IF(R155="","",R155-IF(S155="",0,S155))) -> 242000 | U30: =IF($A155="","",IF(I155="","",I155-SUM(J155:P155))) | V30: NBF 2025年12月期(第49期)決算短信(2026/2/16公表) p.31-32 | W30: 確認済 | X30: テナント又は共有者の同意が得られず収益非開示(短信注3) | Y30: ○（通期保有） | Z30: 年換算可 | AA30: 千円単位（正確値）
A31: NBF-29 | B31: NBF | C31: 2025年12月期（第49期） | D31: 6 | E31: 非開示（テナント同意なし） | F31: 163769 | Q31: =IF($A156="","",IF(OR(F156="",I156=""),"",F156-I156)) | R31: =IF($A156="","",IF(Q156="","",Q156+IF(O156="",0,O156))) | T31: =IF($A156="","",IF(R156="","",R156-IF(S156="",0,S156))) -> 98000 | U31: =IF($A156="","",IF(I156="","",I156-SUM(J156:P156))) | V31: NBF 2025年12月期(第49期)決算短信(2026/2/16公表) p.31-32 | W31: 確認済 | X31: テナント又は共有者の同意が得られず収益非開示(短信注3)。旧NBF新川ビルの取得価格を2020/6/30鑑定評価額比率で按分した金額 | Y31: ○（通期保有） | Z31: 年換算可 | AA31: 千円単位（正確値）
A32: NBF-30 | B32: NBF | C32: 2025年12月期（第49期） | D32: 6 | E32: 開示（物件別・収益のみ、百万円単位） | F32: 185000 | Q32: =IF($A157="","",IF(OR(F157="",I157=""),"",F157-I157)) | R32: =IF($A157="","",IF(Q157="","",Q157+IF(O157="",0,O157))) | T32: =IF($A157="","",IF(R157="","",R157-IF(S157="",0,S157))) -> 19000 | U32: =IF($A157="","",IF(I157="","",I157-SUM(J157:P157))) | V32: NBF 2025年12月期(第49期)決算短信(2026/2/16公表) p.31-32 テナント等の概要 | W32: 確認済 | X32: 総賃貸収入(=当該物件の営業収益計・百万円未満切捨て)を千円換算した概数。費用内訳は物件別非開示(法人一括のNBF-ALL行参照) | Y32: ○（通期保有） | Z32: 年換算可 | AA32: 百万円単位（下3桁は概数）
A33: NBF-31 | B33: NBF | C33: 2025年12月期（第49期） | D33: 6 | E33: 開示（物件別・収益のみ、百万円単位） | F33: 400000 | Q33: =IF($A158="","",IF(OR(F158="",I158=""),"",F158-I158)) | R33: =IF($A158="","",IF(Q158="","",Q158+IF(O158="",0,O158))) | T33: =IF($A158="","",IF(R158="","",R158-IF(S158="",0,S158))) -> 386000 | U33: =IF($A158="","",IF(I158="","",I158-SUM(J158:P158))) | V33: NBF 2025年12月期(第49期)決算短信(2026/2/16公表) p.31-32 テナント等の概要 | W33: 確認済 | X33: 総賃貸収入(=当該物件の営業収益計・百万円未満切捨て)を千円換算した概数。費用内訳は物件別非開示(法人一括のNBF-ALL行参照) | Y33: ○（通期保有） | Z33: 年換算可 | AA33: 百万円単位（下3桁は概数）
A34: NBF-32 | B34: NBF | C34: 2025年12月期（第49期） | D34: 6 | E34: 非開示（テナント同意なし） | F34: 421097 | Q34: =IF($A159="","",IF(OR(F159="",I159=""),"",F159-I159)) | R34: =IF($A159="","",IF(Q159="","",Q159+IF(O159="",0,O159))) | T34: =IF($A159="","",IF(R159="","",R159-IF(S159="",0,S159))) -> 17000 | U34: =IF($A159="","",IF(I159="","",I159-SUM(J159:P159))) | V34: NBF 2025年12月期(第49期)決算短信(2026/2/16公表) p.31-32 | W34: 確認済 | X34: テナント又は共有者の同意が得られず収益非開示(短信注3)。区分所有権(2022〜2024年3回取得・既存保有約47.69%)。2026/3/31付で追加取得予定(約9.19%・14,810百万円→合計約56.88%)。2020年3月竣工・地下2階付36階建・延床178,504.10㎡(建物全体)。店舗区画は固定賃料型ML | Y34: ○（通期保有） | Z34: 年換算可 | AA34: 千円単位（正確値）
A35: NBF-33 | B35: NBF | C35: 2025年12月期（第49期） | D35: 6 | E35: 非開示（テナント同意なし） | F35: 369172 | Q35: =IF($A160="","",IF(OR(F160="",I160=""),"",F160-I160)) | R35: =IF($A160="","",IF(Q160="","",Q160+IF(O160="",0,O160))) | T35: =IF($A160="","",IF(R160="","",R160-IF(S160="",0,S160))) -> 352000 | U35: =IF($A160="","",IF(I160="","",I160-SUM(J160:P160))) | V35: NBF 2025年12月期(第49期)決算短信(2026/2/16公表) p.31-32 | W35: 確認済 | X35: テナント又は共有者の同意が得られず収益非開示(短信注3)。主要テナント:ソニーグループ(賃貸面積73,477㎡=ポートフォリオ全体の6.0%) | Y35: ○（通期保有） | Z35: 年換算可 | AA35: 千円単位（正確値）
A36: NBF-34 | B36: NBF | C36: 2025年12月期（第49期） | D36: 6 | E36: 開示（物件別・収益のみ、百万円単位） | F36: 2084000 | Q36: =IF($A161="","",IF(OR(F161="",I161=""),"",F161-I161)) | R36: =IF($A161="","",IF(Q161="","",Q161+IF(O161="",0,O161))) | T36: =IF($A161="","",IF(R161="","",R161-IF(S161="",0,S161))) -> 9000 | U36: =IF($A161="","",IF(I161="","",I161-SUM(J161:P161))) | V36: NBF 2025年12月期(第49期)決算短信(2026/2/16公表) p.31-32 テナント等の概要 | W36: 確認済 | X36: 総賃貸収入(=当該物件の営業収益計・百万円未満切捨て)を千円換算した概数。費用内訳は物件別非開示(法人一括のNBF-ALL行参照)。2006・2011・2013年の3回取得合計。サブリース型(変動) | Y36: ○（通期保有） | Z36: 年換算可 | AA36: 百万円単位（下3桁は概数）
